Workbook

Sheet Техника
F3: 45992 | I3: 45993 | L3: 45994 | O3: 45995 | R3: 45996 | U3: 45997 | X3: 45998 | AA3: 45999 | AD3: 46000 | AG3: 46001 | AJ3: 46002 | AM3: 46003 | AP3: 46004 | AS3: 46005 | AV3: 46006 | AY3: 46007 | BB3: 46008 | BE3: 46009 | BH3: 46010 | BK3: 46011 | BN3: 46012 | BQ3: 46013 | BT3: 46014 | BW3: 46015 | BZ3: 46016 | CC3: 46017 | CF3: 46018 | CI3: 46019 | CL3: 46020 | CO3: 46021 | CR3: 46022 | CV3: 46023 | CY3: 46024 | DB3: 46025 | DE3: 46026 | DH3: 46027 | DK3: 46028 | DN3: 46029 | DQ3: 46030 | DT3: 46031 | DW3: 46032 | DZ3: 46033 | EC3: 46034 | EF3: 46035 | EI3: 46036 | EL3: 46037 | EO3: 46038 | ER3: 46039 | EU3: 46040 | EX3: 46041 | FA3: 46042 | FD3: 46043 | FG3: 46044 | FJ3: 46045 | FM3: 46046 | FP3: 46047 | FS3: 46048 | FV3: 46049 | FY3: 46050 | GB3: 46051 | GE3: 46052 | GH3: 46053 | GL3: 46054 | GO3: 46055 | GR3: 46056 | GU3: 46057 | GX3: 46058 | HA3: 46059 | HD3: 46060 | HG3: 46061 | HJ3: 46062 | HM3: 46063 | HP3: 46064 | HS3: 46065 | HV3: 46066 | HY3: 46067 | IB3: 46068 | IE3: 46069 | IH3: 46070 | IK3: 46071 | IN3: 46072 | IQ3: 46073 | IT3: 46074 | IW3: 46075 | IZ3: 46076 | JC3: 46077 | JF3: 46078 | JI3: 46079 | JL3: 46080 | JO3: 46081 | JS3: 46082 | JV3: 46083 | JY3: 46084 | KB3: 46085 | KE3: 46086 | KH3: 46087 | KK3: 46088 | KN3: 46089 | KQ3: 46090 | KT3: 46091 | KW3: 46092 | KZ3: 46093 | LC3: 46094 | LF3: 46095 | LI3: 46096 | LL3: 46097 | LO3: 46098 | LR3: 46099 | LU3: 46100 | LX3: 46101 | MA3: 46102 | MD3: 46103 | MG3: 46104 | MJ3: 46105 | MM3: 46106 | MP3: 46107 | MS3: 46108 | MV3: 46109 | MY3: 46110 | NB3: 46111 | NE3: 46112 | NI3: 46113 | NL3: 46114 | NO3: 46115 | NR3: 46116 | NU3: 46117 | NX3: 46118 | OA3: 46119 | OD3: 46120 | OG3: 46121 | OJ3: 46122 | OM3: 46123 | OP3: 46124 | OS3: 46125 | OV3: 46126 | OY3: 46127 | PB3: 46128 | PE3: 46129 | PH3: 46130 | PK3: 46131 | PN3: 46132 | PQ3: 46133 | PT3: 46134 | PW3: 46135 | PZ3: 46136 | QC3: 46137 | QF3: 46138 | QI3: 46139 | QL3: 46140 | QO3: 46141 | QR3: 46142 | QV3: 46143 | QY3: 46144 | RB3: 46145 | RE3: 46146 | RH3: 46147 | RK3: 46148 | RN3: 46149 | RQ3: 46150 | RT3: 46151 | RW3: 46152 | RZ3: 46153 | SC3: 46154 | SF3: 46155 | SI3: 46156 | SL3: 46157 | SO3: 46158 | SR3: 46159 | SU3: 46160 | SX3: 46161 | TA3: 46162 | TD3: 46163 | TG3: 46164 | TJ3: 46165 | TM3: 46166 | TP3: 46167 | TS3: 46168 | TV3: 46169 | TY3: 46170 | UB3: 46171 | UE3: 46172 | UH3: 46173 | UL3: 46174 | UO3: 46175 | UR3: 46176 | UU3: 46177 | UX3: 46178 | VA3: 46179 | VD3: 46180 | VG3: 46181 | VJ3: 46182 | VM3: 46183 | VP3: 46184 | VS3: 46185 | VV3: 46186 | VY3: 46187 | WB3: 46188 | WE3: 46189 | WH3: 46190 | WK3: 46191 | WN3: 46192 | WQ3: 46193 | WT3: 46194 | WW3: 46195 | WZ3: 46196 | XC3: 46197 | XF3: 46198 | XI3: 46199 | XL3: 46200 | XO3: 46201 | XR3: 46202 | XU3: 46203 | XY3: 46204 | YB3: 46205 | YE3: 46206 | YH3: 46207 | YK3: 46208 | YN3: 46209 | YQ3: 46210 | YT3: 46211 | YW3: 46212 | YZ3: 46213 | ZC3: 46214 | ZF3: 46215 | ZI3: 46216 | ZL3: 46217 | ZO3: 46218 | ZR3: 46219 | ZU3: 46220 | ZX3: 46221 | AAA3: 46222 | AAD3: 46223 | AAG3: 46224 | AAJ3: 46225 | AAM3: 46226 | AAP3: 46227 | AAS3: 46228 | AAV3: 46229 | AAY3: 46230 | ABB3: 46231 | ABE3: 46232 | ABH3: 46233 | ABK3: 46234 | ABO3: 46235 | ABR3: 46236 | ABU3: 46237 | ABX3: 46238 | ACA3: 46239 | ACD3: 46240 | ACG3: 46241 | ACJ3: 46242 | ACM3: 46243 | ACP3: 46244 | ACS3: 46245 | ACV3: 46246 | ACY3: 46247 | ADB3: 46248 | ADE3: 46249 | ADH3: 46250 | ADK3: 46251 | ADN3: 46252 | ADQ3: 46253 | ADT3: 46254 | ADW3: 46255 | ADZ3: 46256 | AEC3: 46257 | AEF3: 46258 | AEI3: 46259 | AEL3: 46260 | AEO3: 46261 | AER3: 46262 | AEU3: 46263 | AEX3: 46264 | AFA3: 46265 | AFE3: 46266 | AFH3: 46267 | AFK3: 46268 | AFN3: 46269 | AFQ3: 46270 | AFT3: 46271 | AFW3: 46272 | AFZ3: 46273 | AGC3: 46274 | AGF3: 46275 | AGI3: 46276 | AGL3: 46277 | AGO3: 46278 | AGR3: 46279 | AGU3: 46280 | AGX3: 46281 | AHA3: 46282 | AHD3: 46283 | AHG3: 46284 | AHJ3: 46285 | AHM3: 46286 | AHP3: 46287 | AHS3: 46288 | AHV3: 46289 | AHY3: 46290 | AIB3: 46291 | AIE3: 46292 | AIH3: 46293 | AIK3: 46294 | AIN3: 46295 | AIR3: 46296 | AIU3: 46297 | AIX3: 46298 | AJA3: 46299 | AJD3: 46300 | AJG3: 46301 | AJJ3: 46302 | AJM3: 46303 | AJP3: 46304 | AJS3: 46305 | AJV3: 46306 | AJY3: 46307 | AKB3: 46308 | AKE3: 46309 | AKH3: 46310 | AKK3: 46311 | AKN3: 46312 | AKQ3: 46313 | AKT3: 46314 | AKW3: 46315 | AKZ3: 46316 | ALC3: 46317 | ALF3: 46318 | ALI3: 46319 | ALL3: 46320 | ALO3: 46321 | ALR3: 46322 | ALU3: 46323 | ALX3: 46324 | AMA3: 46325 | AMD3: 46326 | AMH3: 46327 | AMK3: 46328 | AMN3: 46329 | AMQ3: 46330 | AMT3: 46331 | AMW3: 46332 | AMZ3: 46333 | ANC3: 46334 | ANF3: 46335 | ANI3: 46336 | ANL3: 46337 | ANO3: 46338 | ANR3: 46339 | ANU3: 46340 | ANX3: 46341 | AOA3: 46342 | AOD3: 46343 | AOG3: 46344 | AOJ3: 46345 | AOM3: 46346 | AOP3: 46347 | AOS3: 46348 | AOV3: 46349 | AOY3: 46350 | APB3: 46351 | APE3: 46352 | APH3: 46353 | APK3: 46354 | APN3: 46355 | APQ3: 46356 | APU3: 46357 | APX3: 46358 | AQA3: 46359 | AQD3: 46360 | AQG3: 46361 | AQJ3: 46362 | AQM3: 46363 | AQP3: 46364 | AQS3: 46365 | AQV3: 46366 | AQY3: 46367 | ARB3: 46368 | ARE3: 46369 | ARH3: 46370 | ARK3: 46371 | ARN3: 46372 | ARQ3: 46373 | ART3: 46374 | ARW3: 46375 | ARZ3: 46376 | ASC3: 46377 | ASF3: 46378 | ASI3: 46379 | ASL3: 46380 | ASO3: 46381 | ASR3: 46382 | ASU3: 46383 | ASX3: 46384 | ATA3: 46385 | ATD3: 46386 | ATH3: 46388 | ATK3: 46389 | ATN3: 46390 | ATQ3: 46391 | ATT3: 46392 | ATW3: 46393 | ATZ3: 46394 | AUC3: 46395 | AUF3: 46396 | AUI3: 46397 | AUL3: 46398 | AUO3: 46399 | AUR3: 46400 | AUU3: 46401 | AUX3: 46402 | AVA3: 46403 | AVD3: 46404 | AVG3: 46405 | AVJ3: 46406 | AVM3: 46407 | AVP3: 46408 | AVS3: 46409 | AVV3: 46410 | AVY3: 46411 | AWB3: 46412 | AWE3: 46413 | AWH3: 46414 | AWK3: 46415 | AWN3: 46416 | AWQ3: 46417 | AWU3: 46419 | AWX3: 46420 | AXA3: 46421 | AXD3: 46422 | AXG3: 46423 | AXJ3: 46424 | AXM3: 46425 | AXP3: 46426 | AXS3: 46427 | AXV3: 46428 | AXY3: 46429 | AYB3: 46430 | AYE3: 46431 | AYH3: 46432 | AYK3: 46433 | AYN3: 46434 | AYQ3: 46435 | AYT3: 46436 | AYW3: 46437 | AYZ3: 46438 | AZC3: 46439 | AZF3: 46440 | AZI3: 46441 | AZL3: 46442 | AZO3: 46443 | AZR3: 46444 | AZU3: 46445 | AZX3: 46446 | BAB3: 46447 | BAE3: 46448 | BAH3: 46449 | BAK3: 46450 | BAN3: 46451 | BAQ3: 46452 | BAT3: 46453 | BAW3: 46454 | BAZ3: 46455 | BBC3: 46456 | BBF3: 46457 | BBI3: 46458 | BBL3: 46459 | BBO3: 46460 | BBR3: 46461 | BBU3: 46462 | BBX3: 46463 | BCA3: 46464 | BCD3: 46465 | BCG3: 46466 | BCJ3: 46467 | BCM3: 46468 | BCP3: 46469 | BCS3: 46470 | BCV3: 46471 | BCY3: 46472 | BDB3: 46473 | BDE3: 46474 | BDH3: 46475 | BDK3: 46476 | BDN3: 46477 | BDR3: 46478 | BDU3: 46479 | BDX3: 46480 | BEA3: 46481 | BED3: 46482 | BEG3: 46483 | BEJ3: 46484 | BEM3: 46485 | BEP3: 46486 | BES3: 46487 | BEV3: 46488 | BEY3: 46489 | BFB3: 46490 | BFE3: 46491 | BFH3: 46492 | BFK3: 46493 | BFN3: 46494 | BFQ3: 46495 | BFT3: 46496 | BFW3: 46497 | BFZ3: 46498 | BGC3: 46499 | BGF3: 46500 | BGI3: 46501 | BGL3: 46502 | BGO3: 46503 | BGR3: 46504 | BGU3: 46505 | BGX3: 46506 | BHA3: 46507
A4: № п.п. | B4: Марка, модель ТС | C4: Гос.ном.знак | D4: Собственник | F4: Часы | G4: Шифр | H4: Вид. р. | I4: Часы | J4: Шифр | K4: Вид. р. | L4: Часы | M4: Шифр | N4: Вид. р. | O4: Часы | P4: Шифр | Q4: Вид. р. | R4: Часы | S4: Шифр | T4: Вид. р. | U4: Часы | V4: Шифр | W4: Вид. р. | X4: Часы | Y4: Шифр | Z4: Вид. р. | AA4: Часы | AB4: Шифр | AC4: Вид. р. | AD4: Часы | AE4: Шифр | AF4: Вид. р. | AG4: Часы | AH4: Шифр | AI4: Вид. р. | AJ4: Часы | AK4: Шифр | AL4: Вид. р. | AM4: Часы | AN4: Шифр | AO4: Вид. р. | AP4: Часы | AQ4: Шифр | AR4: Вид. р. | AS4: Часы | AT4: Шифр | AU4: Вид. р. | AV4: Часы | AW4: Шифр | AX4: Вид. р. | AY4: Часы | AZ4: Шифр | BA4: Вид. р. | BB4: Часы | BC4: Шифр | BD4: Вид. р. | BE4: Часы | BF4: Шифр | BG4: Вид. р. | BH4: Часы | BI4: Шифр | BJ4: Вид. р. | BK4: Часы | BL4: Шифр | BM4: Вид. р. | BN4: Часы | BO4: Шифр | BP4: Вид. р. | BQ4: Часы | BR4: Шифр | BS4: Вид. р. | BT4: Часы | BU4: Шифр | BV4: Вид. р. | BW4: Часы | BX4: Шифр | BY4: Вид. р. | BZ4: Часы | CA4: Шифр | CB4: Вид. р. | CC4: Часы | CD4: Шифр | CE4: Вид. р. | CF4: Часы | CG4: Шифр | CH4: Вид. р. | CI4: Часы | CJ4: Шифр | CK4: Вид. р. | CL4: Часы | CM4: Шифр | CN4: Вид. р. | CO4: Часы | CP4: Шифр | CQ4: Вид. р. | CR4: Часы | CS4: Шифр | CT4: Вид. р. | CV4: Часы | CW4: Шифр | CX4: Вид. р. | CY4: Часы | CZ4: Шифр | DA4: Вид. р. | DB4: Часы | DC4: Шифр | DD4: Вид. р. | DE4: Часы | DF4: Шифр | DG4: Вид. р. | DH4: Часы | DI4: Шифр | DJ4: Вид. р. | DK4: Часы | DL4: Шифр | DM4: Вид. р. | DN4: Часы | DO4: Шифр | DP4: Вид. р. | DQ4: Часы | DR4: Шифр | DS4: Вид. р. | DT4: Часы | DU4: Шифр | DV4: Вид. р. | DW4: Часы | DX4: Шифр | DY4: Вид. р. | DZ4: Часы | EA4: Шифр | EB4: Вид. р. | EC4: Часы | ED4: Шифр | EE4: Вид. р. | EF4: Часы | EG4: Шифр | EH4: Вид. р. | EI4: Часы | EJ4: Шифр | EK4: Вид. р. | EL4: Часы | EM4: Шифр | EN4: Вид. р. | EO4: Часы | EP4: Шифр | EQ4: Вид. р. | ER4: Часы | ES4: Шифр | ET4: Вид. р. | EU4: Часы | EV4: Шифр | EW4: Вид. р. | EX4: Часы | EY4: Шифр | EZ4: Вид. р. | FA4: Часы | FB4: Шифр | FC4: Вид. р. | FD4: Часы | FE4: Шифр | FF4: Вид. р. | FG4: Часы | FH4: Шифр | FI4: Вид. р. | FJ4: Часы | FK4: Шифр | FL4: Вид. р. | FM4: Часы | FN4: Шифр | FO4: Вид. р. | FP4: Часы | FQ4: Шифр | FR4: Вид. р. | FS4: Часы | FT4: Шифр | FU4: Вид. р. | FV4: Часы | FW4: Шифр | FX4: Вид. р. | FY4: Часы | FZ4: Шифр | GA4: Вид. р. | GB4: Часы | GC4: Шифр | GD4: Вид. р. | GE4: Часы | GF4: Шифр | GG4: Вид. р. | GH4: Часы | GI4: Шифр | GJ4: Вид. р. | GL4: Часы | GM4: Шифр | GN4: Вид. р. | GO4: Часы | GP4: Шифр | GQ4: Вид. р. | GR4: Часы | GS4: Шифр | GT4: Вид. р. | GU4: Часы | GV4: Шифр | GW4: Вид. р. | GX4: Часы | GY4: Шифр | GZ4: Вид. р. | HA4: Часы | HB4: Шифр | HC4: Вид. р. | HD4: Часы | HE4: Шифр | HF4: Вид. р. | HG4: Часы | HH4: Шифр | HI4: Вид. р. | HJ4: Часы | HK4: Шифр | HL4: Вид. р. | HM4: Часы | HN4: Шифр | HO4: Вид. р. | HP4: Часы | HQ4: Шифр | HR4: Вид. р. | HS4: Часы | HT4: Шифр | HU4: Вид. р. | HV4: Часы | HW4: Шифр | HX4: Вид. р. | HY4: Часы | HZ4: Шифр | IA4: Вид. р. | IB4: Часы | IC4: Шифр | ID4: Вид. р. | IE4: Часы | IF4: Шифр | IG4: Вид. р. | IH4: Часы | II4: Шифр | IJ4: Вид. р. | IK4: Часы | IL4: Шифр | IM4: Вид. р. | IN4: Часы | IO4: Шифр | IP4: Вид. р. | IQ4: Часы | IR4: Шифр | IS4: Вид. р. | IT4: Часы | IU4: Шифр | IV4: Вид. р. | IW4: Часы | IX4: Шифр | IY4: Вид. р. | IZ4: Часы | JA4: Шифр | JB4: Вид. р. | JC4: Часы | JD4: Шифр | JE4: Вид. р. | JF4: Часы | JG4: Шифр | JH4: Вид. р. | JI4: Часы | JJ4: Шифр | JK4: Вид. р. | JL4: Часы | JM4: Шифр | JN4: Вид. р. | JO4: Часы | JP4: Шифр | JQ4: Вид. р. | JS4: Часы | JT4: Шифр | JU4: Вид. р. | JV4: Часы | JW4: Шифр | JX4: Вид. р. | JY4: Часы | JZ4: Шифр | KA4: Вид. р. | KB4: Часы | KC4: Шифр | KD4: Вид. р. | KE4: Часы | KF4: Шифр | KG4: Вид. р. | KH4: Часы | KI4: Шифр | KJ4: Вид. р. | KK4: Часы | KL4: Шифр | KM4: Вид. р. | KN4: Часы | KO4: Шифр | KP4: Вид. р. | KQ4: Часы | KR4: Шифр | KS4: Вид. р. | KT4: Часы | KU4: Шифр | KV4: Вид. р. | KW4: Часы | KX4: Шифр | KY4: Вид. р. | KZ4: Часы | LA4: Шифр | LB4: Вид. р. | LC4: Часы | LD4: Шифр | LE4: Вид. р. | LF4: Часы | LG4: Шифр | LH4: Вид. р. | LI4: Часы | LJ4: Шифр | LK4: Вид. р. | LL4: Часы | LM4: Шифр | LN4: Вид. р. | LO4: Часы | LP4: Шифр | LQ4: Вид. р. | LR4: Часы | LS4: Шифр | LT4: Вид. р. | LU4: Часы | LV4: Шифр | LW4: Вид. р. | LX4: Часы | LY4: Шифр | LZ4: Вид. р. | MA4: Часы | MB4: Шифр | MC4: Вид. р. | MD4: Часы | ME4: Шифр | MF4: Вид. р. | MG4: Часы | MH4: Шифр | MI4: Вид. р. | MJ4: Часы | MK4: Шифр | ML4: Вид. р. | MM4: Часы | MN4: Шифр | MO4: Вид. р. | MP4: Часы | MQ4: Шифр | MR4: Вид. р. | MS4: Часы | MT4: Шифр | MU4: Вид. р. | MV4: Часы | MW4: Шифр | MX4: Вид. р. | MY4: Часы | MZ4: Шифр | NA4: Вид. р. | NB4: Часы | NC4: Шифр | ND4: Вид. р. | NE4: Часы | NF4: Шифр | NG4: Вид. р. | NI4: Часы | NJ4: Шифр | NK4: Вид. р. | NL4: Часы | NM4: Шифр | NN4: Вид. р. | NO4: Часы | NP4: Шифр | NQ4: Вид. р. | NR4: Часы | NS4: Шифр | NT4: Вид. р. | NU4: Часы | NV4: Шифр | NW4: Вид. р. | NX4: Часы | NY4: Шифр | NZ4: Вид. р. | OA4: Часы | OB4: Шифр | OC4: Вид. р. | OD4: Часы | OE4: Шифр | OF4: Вид. р. | OG4: Часы | OH4: Шифр | OI4: Вид. р. | OJ4: Часы | OK4: Шифр | OL4: Вид. р. | OM4: Часы | ON4: Шифр | OO4: Вид. р. | OP4: Часы | OQ4: Шифр | OR4: Вид. р. | OS4: Часы | OT4: Шифр | OU4: Вид. р. | OV4: Часы | OW4: Шифр | OX4: Вид. р. | OY4: Часы | OZ4: Шифр | PA4: Вид. р. | PB4: Часы | PC4: Шифр | PD4: Вид. р. | PE4: Часы | PF4: Шифр | PG4: Вид. р. | PH4: Часы | PI4: Шифр | PJ4: Вид. р. | PK4: Часы | PL4: Шифр | PM4: Вид. р. | PN4: Часы | PO4: Шифр | PP4: Вид. р. | PQ4: Часы | PR4: Шифр | PS4: Вид. р. | PT4: Часы | PU4: Шифр | PV4: Вид. р. | PW4: Часы | PX4: Шифр | PY4: Вид. р. | PZ4: Часы | QA4: Шифр | QB4: Вид. р. | QC4: Часы | QD4: Шифр | QE4: Вид. р. | QF4: Часы | QG4: Шифр | QH4: Вид. р. | QI4: Часы | QJ4: Шифр | QK4: Вид. р. | QL4: Часы | QM4: Шифр | QN4: Вид. р. | QO4: Часы | QP4: Шифр | QQ4: Вид. р. | QR4: Часы | QS4: Шифр | QT4: Вид. р. | QV4: Часы | QW4: Шифр | QX4: Вид. р. | QY4: Часы | QZ4: Шифр | RA4: Вид. р. | RB4: Часы | RC4: Шифр | RD4: Вид. р. | RE4: Часы | RF4: Шифр | RG4: Вид. р. | RH4: Часы | RI4: Шифр | RJ4: Вид. р. | RK4: Часы | RL4: Шифр | RM4: Вид. р. | RN4: Часы | RO4: Шифр | RP4: Вид. р. | RQ4: Часы | RR4: Шифр | RS4: Вид. р. | RT4: Часы | RU4: Шифр | RV4: Вид. р. | RW4: Часы | RX4: Шифр | RY4: Вид. р. | RZ4: Часы | SA4: Шифр | SB4: Вид. р. | SC4: Часы | SD4: Шифр | SE4: Вид. р. | SF4: Часы | SG4: Шифр | SH4: Вид. р. | SI4: Часы | SJ4: Шифр | SK4: Вид. р. | SL4: Часы | SM4: Шифр | SN4: Вид. р. | SO4: Часы | SP4: Шифр | SQ4: Вид. р. | SR4: Часы | SS4: Шифр | ST4: Вид. р. | SU4: Часы | SV4: Шифр | SW4: Вид. р. | SX4: Часы | SY4: Шифр | SZ4: Вид. р. | TA4: Часы | TB4: Шифр | TC4: Вид. р. | TD4: Часы | TE4: Шифр | TF4: Вид. р. | TG4: Часы | TH4: Шифр | TI4: Вид. р. | TJ4: Часы | TK4: Шифр | TL4: Вид. р. | TM4: Часы | TN4: Шифр | TO4: Вид. р. | TP4: Часы | TQ4: Шифр | TR4: Вид. р. | TS4: Часы | TT4: Шифр | TU4: Вид. р. | TV4: Часы | TW4: Шифр | TX4: Вид. р. | TY4: Часы | TZ4: Шифр | UA4: Вид. р. | UB4: Часы | UC4: Шифр | UD4: Вид. р. | UE4: Часы | UF4: Шифр | UG4: Вид. р. | UH4: Часы | UI4: Шифр | UJ4: Вид. р. | UL4: Часы | UM4: Шифр | UN4: Вид. р. | UO4: Часы | UP4: Шифр | UQ4: Вид. р. | UR4: Часы | US4: Шифр | UT4: Вид. р. | UU4: Часы | UV4: Шифр | UW4: Вид. р. | UX4: Часы | UY4: Шифр | UZ4: Вид. р. | VA4: Часы | VB4: Шифр | VC4: Вид. р. | VD4: Часы | VE4: Шифр | VF4: Вид. р. | VG4: Часы | VH4: Шифр | VI4: Вид. р. | VJ4: Часы | VK4: Шифр | VL4: Вид. р. | VM4: Часы | VN4: Шифр | VO4: Вид. р. | VP4: Часы | VQ4: Шифр | VR4: Вид. р. | VS4: Часы | VT4: Шифр | VU4: Вид. р. | VV4: Часы | VW4: Шифр | VX4: Вид. р. | VY4: Часы | VZ4: Шифр | WA4: Вид. р. | WB4: Часы | WC4: Шифр | WD4: Вид. р. | WE4: Часы | WF4: Шифр | WG4: Вид. р. | WH4: Часы | WI4: Шифр | WJ4: Вид. р. | WK4: Часы | WL4: Шифр | WM4: Вид. р. | WN4: Часы | WO4: Шифр | WP4: Вид. р. | WQ4: Часы | WR4: Шифр | WS4: Вид. р. | WT4: Часы | WU4: Шифр | WV4: Вид. р. | WW4: Часы | WX4: Шифр | WY4: Вид. р. | WZ4: Часы | XA4: Шифр | XB4: Вид. р. | XC4: Часы | XD4: Шифр | XE4: Вид. р. | XF4: Часы | XG4: Шифр | XH4: Вид. р. | XI4: Часы | XJ4: Шифр | XK4: Вид. р. | XL4: Часы | XM4: Шифр | XN4: Вид. р. | XO4: Часы | XP4: Шифр | XQ4: Вид. р. | XR4: Часы | XS4: Шифр | XT4: Вид. р. | XU4: Часы | XV4: Шифр | XW4: Вид. р. | XY4: Часы | XZ4: Шифр | YA4: Вид. р. | YB4: Часы | YC4: Шифр | YD4: Вид. р. | YE4: Часы | YF4: Шифр | YG4: Вид. р. | YH4: Часы | YI4: Шифр | YJ4: Вид. р. | YK4: Часы | YL4: Шифр | YM4: Вид. р. | YN4: Часы | YO4: Шифр | YP4: Вид. р. | YQ4: Часы | YR4: Шифр | YS4: Вид. р. | YT4: Часы | YU4: Шифр | YV4: Вид. р. | YW4: Часы | YX4: Шифр | YY4: Вид. р. | YZ4: Часы | ZA4: Шифр | ZB4: Вид. р. | ZC4: Часы | ZD4: Шифр | ZE4: Вид. р. | ZF4: Часы | ZG4: Шифр | ZH4: Вид. р. | ZI4: Часы | ZJ4: Шифр | ZK4: Вид. р. | ZL4: Часы | ZM4: Шифр | ZN4: Вид. р. | ZO4: Часы | ZP4: Шифр | ZQ4: Вид. р. | ZR4: Часы | ZS4: Шифр | ZT4: Вид. р. | ZU4: Часы | ZV4: Шифр | ZW4: Вид. р. | ZX4: Часы | ZY4: Шифр | ZZ4: Вид. р. | AAA4: Часы | AAB4: Шифр | AAC4: Вид. р. | AAD4: Часы | AAE4: Шифр | AAF4: Вид. р. | AAG4: Часы | AAH4: Шифр | AAI4: Вид. р. | AAJ4: Часы | AAK4: Шифр | AAL4: Вид. р. | AAM4: Часы | AAN4: Шифр | AAO4: Вид. р. | AAP4: Часы | AAQ4: Шифр | AAR4: Вид. р. | AAS4: Часы | AAT4: Шифр | AAU4: Вид. р. | AAV4: Часы | AAW4: Шифр | AAX4: Вид. р. | AAY4: Часы | AAZ4: Шифр | ABA4: Вид. р. | ABB4: Часы | ABC4: Шифр | ABD4: Вид. р. | ABE4: Часы | ABF4: Шифр | ABG4: Вид. р. | ABH4: Часы | ABI4: Шифр | ABJ4: Вид. р. | ABK4: Часы | ABL4: Шифр | ABM4: Вид. р. | ABO4: Часы | ABP4: Шифр | ABQ4: Вид. р. | ABR4: Часы | ABS4: Шифр | ABT4: Вид. р. | ABU4: Часы | ABV4: Шифр | ABW4: Вид. р. | ABX4: Часы | ABY4: Шифр | ABZ4: Вид. р. | ACA4: Часы | ACB4: Шифр | ACC4: Вид. р. | ACD4: Часы | ACE4: Шифр | ACF4: Вид. р. | ACG4: Часы | ACH4: Шифр | ACI4: Вид. р. | ACJ4: Часы | ACK4: Шифр | ACL4: Вид. р. | ACM4: Часы | ACN4: Шифр | ACO4: Вид. р. | ACP4: Часы | ACQ4: Шифр | ACR4: Вид. р. | ACS4: Часы | ACT4: Шифр | ACU4: Вид. р. | ACV4: Часы | ACW4: Шифр | ACX4: Вид. р. | ACY4: Часы | ACZ4: Шифр | ADA4: Вид. р. | ADB4: Часы | ADC4: Шифр | ADD4: Вид. р. | ADE4: Часы | ADF4: Шифр | ADG4: Вид. р. | ADH4: Часы | ADI4: Шифр | ADJ4: Вид. р. | ADK4: Часы | ADL4: Шифр | ADM4: Вид. р. | ADN4: Часы | ADO4: Шифр | ADP4: Вид. р. | ADQ4: Часы | ADR4: Шифр | ADS4: Вид. р. | ADT4: Часы | ADU4: Шифр | ADV4: Вид. р. | ADW4: Часы | ADX4: Шифр | ADY4: Вид. р. | ADZ4: Часы | AEA4: Шифр | AEB4: Вид. р. | AEC4: Часы | AED4: Шифр | AEE4: Вид. р. | AEF4: Часы | AEG4: Шифр | AEH4: Вид. р. | AEI4: Часы | AEJ4: Шифр | AEK4: Вид. р. | AEL4: Часы | AEM4: Шифр | AEN4: Вид. р. | AEO4: Часы | AEP4: Шифр | AEQ4: Вид. р. | AER4: Часы | AES4: Шифр | AET4: Вид. р. | AEU4: Часы | AEV4: Шифр | AEW4: Вид. р. | AEX4: Часы | AEY4: Шифр | AEZ4: Вид. р. | AFA4: Часы | AFB4: Шифр | AFC4: Вид. р. | AFE4: Часы | AFF4: Шифр | AFG4: Вид. р. | AFH4: Часы | AFI4: Шифр | AFJ4: Вид. р. | AFK4: Часы | AFL4: Шифр | AFM4: Вид. р. | AFN4: Часы | AFO4: Шифр | AFP4: Вид. р. | AFQ4: Часы | AFR4: Шифр | AFS4: Вид. р. | AFT4: Часы | AFU4: Шифр | AFV4: Вид. р. | AFW4: Часы | AFX4: Шифр | AFY4: Вид. р. | AFZ4: Часы | AGA4: Шифр | AGB4: Вид. р. | AGC4: Часы | AGD4: Шифр | AGE4: Вид. р. | AGF4: Часы | AGG4: Шифр | AGH4: Вид. р. | AGI4: Часы | AGJ4: Шифр | AGK4: Вид. р. | AGL4: Часы | AGM4: Шифр | AGN4: Вид. р. | AGO4: Часы | AGP4: Шифр | AGQ4: Вид. р. | AGR4: Часы | AGS4: Шифр | AGT4: Вид. р. | AGU4: Часы | AGV4: Шифр | AGW4: Вид. р. | AGX4: Часы | AGY4: Шифр | AGZ4: Вид. р. | AHA4: Часы | AHB4: Шифр | AHC4: Вид. р. | AHD4: Часы | AHE4: Шифр | AHF4: Вид. р. | AHG4: Часы | AHH4: Шифр | AHI4: Вид. р. | AHJ4: Часы | AHK4: Шифр | AHL4: Вид. р. | AHM4: Часы | AHN4: Шифр | AHO4: Вид. р. | AHP4: Часы | AHQ4: Шифр | AHR4: Вид. р. | AHS4: Часы | AHT4: Шифр | AHU4: Вид. р. | AHV4: Часы | AHW4: Шифр | AHX4: Вид. р. | AHY4: Часы | AHZ4: Шифр | AIA4: Вид. р. | AIB4: Часы | AIC4: Шифр | AID4: Вид. р. | AIE4: Часы | AIF4: Шифр | AIG4: Вид. р. | AIH4: Часы | AII4: Шифр | AIJ4: Вид. р. | AIK4: Часы | AIL4: Шифр | AIM4: Вид. р. | AIN4: Часы | AIO4: Шифр | AIP4: Вид. р. | AIR4: Часы | AIS4: Шифр | AIT4: Вид. р. | AIU4: Часы | AIV4: Шифр | AIW4: Вид. р. | AIX4: Часы | AIY4: Шифр | AIZ4: Вид. р. | AJA4: Часы | AJB4: Шифр | AJC4: Вид. р. | AJD4: Часы | AJE4: Шифр | AJF4: Вид. р. | AJG4: Часы | AJH4: Шифр | AJI4: Вид. р. | AJJ4: Часы | AJK4: Шифр | AJL4: Вид. р. | AJM4: Часы | AJN4: Шифр | AJO4: Вид. р. | AJP4: Часы | AJQ4: Шифр | AJR4: Вид. р. | AJS4: Часы | AJT4: Шифр | AJU4: Вид. р. | AJV4: Часы | AJW4: Шифр | AJX4: Вид. р. | AJY4: Часы | AJZ4: Шифр | AKA4: Вид. р. | AKB4: Часы | AKC4: Шифр | AKD4: Вид. р. | AKE4: Часы | AKF4: Шифр | AKG4: Вид. р. | AKH4: Часы | AKI4: Шифр | AKJ4: Вид. р. | AKK4: Часы | AKL4: Шифр | AKM4: Вид. р. | AKN4: Часы | AKO4: Шифр | AKP4: Вид. р. | AKQ4: Часы | AKR4: Шифр | AKS4: Вид. р. | AKT4: Часы | AKU4: Шифр | AKV4: Вид. р. | AKW4: Часы | AKX4: Шифр | AKY4: Вид. р. | AKZ4: Часы | ALA4: Шифр | ALB4: Вид. р. | ALC4: Часы | ALD4: Шифр | ALE4: Вид. р. | ALF4: Часы | ALG4: Шифр | ALH4: Вид. р. | ALI4: Часы | ALJ4: Шифр | ALK4: Вид. р. | ALL4: Часы | ALM4: Шифр | ALN4: Вид. р. | ALO4: Часы | ALP4: Шифр | ALQ4: Вид. р. | ALR4: Часы | ALS4: Шифр | ALT4: Вид. р. | ALU4: Часы | ALV4: Шифр | ALW4: Вид. р. | ALX4: Часы | ALY4: Шифр | ALZ4: Вид. р. | AMA4: Часы | AMB4: Шифр | AMC4: Вид. р. | AMD4: Часы | AME4: Шифр | AMF4: Вид. р. | AMH4: Часы | AMI4: Шифр | AMJ4: Вид. р. | AMK4: Часы | AML4: Шифр | AMM4: Вид. р. | AMN4: Часы | AMO4: Шифр | AMP4: Вид. р. | AMQ4: Часы | AMR4: Шифр | AMS4: Вид. р. | AMT4: Часы | AMU4: Шифр | AMV4: Вид. р. | AMW4: Часы | AMX4: Шифр | AMY4: Вид. р. | AMZ4: Часы | ANA4: Шифр | ANB4: Вид. р. | ANC4: Часы | AND4: Шифр | ANE4: Вид. р. | ANF4: Часы | ANG4: Шифр | ANH4: Вид. р. | ANI4: Часы | ANJ4: Шифр | ANK4: Вид. р. | ANL4: Часы | ANM4: Шифр | ANN4: Вид. р. | ANO4: Часы | ANP4: Шифр | ANQ4: Вид. р. | ANR4: Часы | ANS4: Шифр | ANT4: Вид. р. | ANU4: Часы | ANV4: Шифр | ANW4: Вид. р. | ANX4: Часы | ANY4: Шифр | ANZ4: Вид. р. | AOA4: Часы | AOB4: Шифр | AOC4: Вид. р. | AOD4: Часы | AOE4: Шифр | AOF4: Вид. р. | AOG4: Часы | AOH4: Шифр | AOI4: Вид. р. | AOJ4: Часы | AOK4: Шифр | AOL4: Вид. р. | AOM4: Часы | AON4: Шифр | AOO4: Вид. р. | AOP4: Часы | AOQ4: Шифр | AOR4: Вид. р. | AOS4: Часы | AOT4: Шифр | AOU4: Вид. р. | AOV4: Часы | AOW4: Шифр | AOX4: Вид. р. | AOY4: Часы | AOZ4: Шифр | APA4: Вид. р. | APB4: Часы | APC4: Шифр | APD4: Вид. р. | APE4: Часы | APF4: Шифр | APG4: Вид. р. | APH4: Часы | API4: Шифр | APJ4: Вид. р. | APK4: Часы | APL4: Шифр | APM4: Вид. р. | APN4: Часы | APO4: Шифр | APP4: Вид. р. | APQ4: Часы | APR4: Шифр | APS4: Вид. р. | APU4: Часы | APV4: Шифр | APW4: Вид. р. | APX4: Часы | APY4: Шифр | APZ4: Вид. р. | AQA4: Часы | AQB4: Шифр | AQC4: Вид. р. | AQD4: Часы | AQE4: Шифр | AQF4: Вид. р. | AQG4: Часы | AQH4: Шифр | AQI4: Вид. р. | AQJ4: Часы | AQK4: Шифр | AQL4: Вид. р. | AQM4: Часы | AQN4: Шифр | AQO4: Вид. р. | AQP4: Часы | AQQ4: Шифр | AQR4: Вид. р. | AQS4: Часы | AQT4: Шифр | AQU4: Вид. р. | AQV4: Часы | AQW4: Шифр | AQX4: Вид. р. | AQY4: Часы | AQZ4: Шифр | ARA4: Вид. р. | ARB4: Часы | ARC4: Шифр | ARD4: Вид. р. | ARE4: Часы | ARF4: Шифр | ARG4: Вид. р. | ARH4: Часы | ARI4: Шифр | ARJ4: Вид. р. | ARK4: Часы | ARL4: Шифр | ARM4: Вид. р. | ARN4: Часы | ARO4: Шифр | ARP4: Вид. р. | ARQ4: Часы | ARR4: Шифр | ARS4: Вид. р. | ART4: Часы | ARU4: Шифр | ARV4: Вид. р. | ARW4: Часы | ARX4: Шифр | ARY4: Вид. р. | ARZ4: Часы | ASA4: Шифр | ASB4: Вид. р. | ASC4: Часы | ASD4: Шифр | ASE4: Вид. р. | ASF4: Часы | ASG4: Шифр | ASH4: Вид. р. | ASI4: Часы | ASJ4: Шифр | ASK4: Вид. р. | ASL4: Часы | ASM4: Шифр | ASN4: Вид. р. | ASO4: Часы | ASP4: Шифр | ASQ4: Вид. р. | ASR4: Часы | ASS4: Шифр | AST4: Вид. р. | ASU4: Часы | ASV4: Шифр | ASW4: Вид. р. | ASX4: Часы | ASY4: Шифр | ASZ4: Вид. р. | ATA4: Часы | ATB4: Шифр | ATC4: Вид. р. | ATD4: Часы | ATE4: Шифр | ATF4: Вид. р. | ATH4: Часы | ATI4: Шифр | ATJ4: Вид. р. | ATK4: Часы | ATL4: Шифр | ATM4: Вид. р. | ATN4: Часы | ATO4: Шифр | ATP4: Вид. р. | ATQ4: Часы | ATR4: Шифр | ATS4: Вид. р. | ATT4: Часы | ATU4: Шифр | ATV4: Вид. р. | ATW4: Часы | ATX4: Шифр | ATY4: Вид. р. | ATZ4: Часы | AUA4: Шифр | AUB4: Вид. р. | AUC4: Часы | AUD4: Шифр | AUE4: Вид. р. | AUF4: Часы | AUG4: Шифр | AUH4: Вид. р. | AUI4: Часы | AUJ4: Шифр | AUK4: Вид. р. | AUL4: Часы | AUM4: Шифр | AUN4: Вид. р. | AUO4: Часы | AUP4: Шифр | AUQ4: Вид. р. | AUR4: Часы | AUS4: Шифр | AUT4: Вид. р. | AUU4: Часы | AUV4: Шифр | AUW4: Вид. р. | AUX4: Часы | AUY4: Шифр | AUZ4: Вид. р. | AVA4: Часы | AVB4: Шифр | AVC4: Вид. р. | AVD4: Часы | AVE4: Шифр | AVF4: Вид. р. | AVG4: Часы | AVH4: Шифр | AVI4: Вид. р. | AVJ4: Часы | AVK4: Шифр | AVL4: Вид. р. | AVM4: Часы | AVN4: Шифр | AVO4: Вид. р. | AVP4: Часы | AVQ4: Шифр | AVR4: Вид. р. | AVS4: Часы | AVT4: Шифр | AVU4: Вид. р. | AVV4: Часы | AVW4: Шифр | AVX4: Вид. р. | AVY4: Часы | AVZ4: Шифр | AWA4: Вид. р. | AWB4: Часы | AWC4: Шифр | AWD4: Вид. р. | AWE4: Часы | AWF4: Шифр | AWG4: Вид. р. | AWH4: Часы | AWI4: Шифр | AWJ4: Вид. р. | AWK4: Часы | AWL4: Шифр | AWM4: Вид. р. | AWN4: Часы | AWO4: Шифр | AWP4: Вид. р. | AWQ4: Часы | AWR4: Шифр | AWS4: Вид. р. | AWU4: Часы | AWV4: Шифр | AWW4: Вид. р. | AWX4: Часы | AWY4: Шифр | AWZ4: Вид. р. | AXA4: Часы | AXB4: Шифр | AXC4: Вид. р. | AXD4: Часы | AXE4: Шифр | AXF4: Вид. р. | AXG4: Часы | AXH4: Шифр | AXI4: Вид. р. | AXJ4: Часы | AXK4: Шифр | AXL4: Вид. р. | AXM4: Часы | AXN4: Шифр | AXO4: Вид. р. | AXP4: Часы | AXQ4: Шифр | AXR4: Вид. р. | AXS4: Часы | AXT4: Шифр | AXU4: Вид. р. | AXV4: Часы | AXW4: Шифр | AXX4: Вид. р. | AXY4: Часы | AXZ4: Шифр | AYA4: Вид. р. | AYB4: Часы | AYC4: Шифр | AYD4: Вид. р. | AYE4: Часы | AYF4: Шифр | AYG4: Вид. р. | AYH4: Часы | AYI4: Шифр | AYJ4: Вид. р. | AYK4: Часы | AYL4: Шифр | AYM4: Вид. р. | AYN4: Часы | AYO4: Шифр | AYP4: Вид. р. | AYQ4: Часы | AYR4: Шифр | AYS4: Вид. р. | AYT4: Часы | AYU4: Шифр | AYV4: Вид. р. | AYW4: Часы | AYX4: Шифр | AYY4: Вид. р. | AYZ4: Часы | AZA4: Шифр | AZB4: Вид. р. | AZC4: Часы | AZD4: Шифр | AZE4: Вид. р. | AZF4: Часы | AZG4: Шифр | AZH4: Вид. р. | AZI4: Часы | AZJ4: Шифр | AZK4: Вид. р. | AZL4: Часы | AZM4: Шифр | AZN4: Вид. р. | AZO4: Часы | AZP4: Шифр | AZQ4: Вид. р. | AZR4: Часы | AZS4: Шифр | AZT4: Вид. р. | AZU4: Часы | AZV4: Шифр | AZW4: Вид. р. | AZX4: Часы | AZY4: Шифр | AZZ4: Вид. р. | BAB4: Часы | BAC4: Шифр | BAD4: Вид. р. | BAE4: Часы | BAF4: Шифр | BAG4: Вид. р. | BAH4: Часы | BAI4: Шифр | BAJ4: Вид. р. | BAK4: Часы | BAL4: Шифр | BAM4: Вид. р. | BAN4: Часы | BAO4: Шифр | BAP4: Вид. р. | BAQ4: Часы | BAR4: Шифр | BAS4: Вид. р. | BAT4: Часы | BAU4: Шифр | BAV4: Вид. р. | BAW4: Часы | BAX4: Шифр | BAY4: Вид. р. | BAZ4: Часы | BBA4: Шифр | BBB4: Вид. р. | BBC4: Часы | BBD4: Шифр | BBE4: Вид. р. | BBF4: Часы | BBG4: Шифр | BBH4: Вид. р. | BBI4: Часы | BBJ4: Шифр | BBK4: Вид. р. | BBL4: Часы | BBM4: Шифр | BBN4: Вид. р. | BBO4: Часы | BBP4: Шифр | BBQ4: Вид. р. | BBR4: Часы | BBS4: Шифр | BBT4: Вид. р. | BBU4: Часы | BBV4: Шифр | BBW4: Вид. р. | BBX4: Часы | BBY4: Шифр | BBZ4: Вид. р. | BCA4: Часы | BCB4: Шифр | BCC4: Вид. р. | BCD4: Часы | BCE4: Шифр | BCF4: Вид. р. | BCG4: Часы | BCH4: Шифр | BCI4: Вид. р. | BCJ4: Часы | BCK4: Шифр | BCL4: Вид. р. | BCM4: Часы | BCN4: Шифр | BCO4: Вид. р. | BCP4: Часы | BCQ4: Шифр | BCR4: Вид. р. | BCS4: Часы | BCT4: Шифр | BCU4: Вид. р. | BCV4: Часы | BCW4: Шифр | BCX4: Вид. р. | BCY4: Часы | BCZ4: Шифр | BDA4: Вид. р. | BDB4: Часы | BDC4: Шифр | BDD4: Вид. р. | BDE4: Часы | BDF4: Шифр | BDG4: Вид. р. | BDH4: Часы | BDI4: Шифр | BDJ4: Вид. р. | BDK4: Часы | BDL4: Шифр | BDM4: Вид. р. | BDN4: Часы | BDO4: Шифр | BDP4: Вид. р. | BDR4: Часы | BDS4: Шифр | BDT4: Вид. р. | BDU4: Часы | BDV4: Шифр | BDW4: Вид. р. | BDX4: Часы | BDY4: Шифр | BDZ4: Вид. р. | BEA4: Часы | BEB4: Шифр | BEC4: Вид. р. | BED4: Часы | BEE4: Шифр | BEF4: Вид. р. | BEG4: Часы | BEH4: Шифр | BEI4: Вид. р. | BEJ4: Часы | BEK4: Шифр | BEL4: Вид. р. | BEM4: Часы | BEN4: Шифр | BEO4: Вид. р. | BEP4: Часы | BEQ4: Шифр | BER4: Вид. р. | BES4: Часы | BET4: Шифр | BEU4: Вид. р. | BEV4: Часы | BEW4: Шифр | BEX4: Вид. р. | BEY4: Часы | BEZ4: Шифр | BFA4: Вид. р. | BFB4: Часы | BFC4: Шифр | BFD4: Вид. р. | BFE4: Часы | BFF4: Шифр | BFG4: Вид. р. | BFH4: Часы | BFI4: Шифр | BFJ4: Вид. р. | BFK4: Часы | BFL4: Шифр | BFM4: Вид. р. | BFN4: Часы | BFO4: Шифр | BFP4: Вид. р. | BFQ4: Часы | BFR4: Шифр | BFS4: Вид. р. | BFT4: Часы | BFU4: Шифр | BFV4: Вид. р. | BFW4: Часы | BFX4: Шифр | BFY4: Вид. р. | BFZ4: Часы | BGA4: Шифр | BGB4: Вид. р. | BGC4: Часы | BGD4: Шифр | BGE4: Вид. р. | BGF4: Часы | BGG4: Шифр | BGH4: Вид. р. | BGI4: Часы | BGJ4: Шифр | BGK4: Вид. р. | BGL4: Часы | BGM4: Шифр | BGN4: Вид. р. | BGO4: Часы | BGP4: Шифр | BGQ4: Вид. р. | BGR4: Часы | BGS4: Шифр | BGT4: Вид. р. | BGU4: Часы | BGV4: Шифр | BGW4: Вид. р. | BGX4: Часы | BGY4: Шифр | BGZ4: Вид. р. | BHA4: Часы | BHB4: Шифр | BHC4: Вид. р.
A5: 1 | B5: Renault Duster (Е 066 КМ 164) | C5: Е 066 КМ 164 | D5: ООО ФДС
A6: 2 | B6: КАМАЗ длинномер К1Е1А6 с КМУ (Х 726 СХ 797) | C6: Х 726 СХ 797 | D6: ООО ФДС | RE6: 8 | RF6: 228 | RG6: П | RN6: 8 | RO6: 228 | RP6: П | RQ6: 8 | RR6: 228 | RS6: П | SC6: 8 | SD6: 228 | SE6: П | SF6: 8 | SG6: 228 | SH6: П | SI6: 8 | SJ6: 228 | SK6: П | SL6: 8 | SM6: 228 | SN6: П | SU6: 8 | SV6: 228 | SW6: П | SX6: 8 | SY6: 228 | SZ6: П | TA6: 8 | TB6: 228 | TC6: П | TD6: 8 | TE6: 228 | TF6: П | TP6: 8 | TQ6: 45 | TR6: М | TS6: 8 | TT6: 45 | TU6: М | TV6: 8 | TW6: 45 | TX6: М | ABB6: 8 | ABC6: 80 | ABD6: П
A7: 3 | B7: Экскаватор погрузчик JCB (0634 АА 64) | C7: 0634 АА 64 | D7: ООО ФДС
A8: 4 | B8: Автобус ПАЗ (30 мест) (К 098 ВК 164) | C8: К 098 ВК 164 | D8: ООО ФДС
A9: 5 | B9: МАЗ 6501В9-8420-000 (Грузовой самосвал) (А 347 ЕМ 164) | C9: А 347 ЕМ 164 | D9: ООО ФДС
A10: 6 | B10: Виброкаток Bomag BMP 8500 1,6т (6038 СМ 64) | C10: 6038 СМ 64 | D10: ООО ФДС
A11: 7 | B11: FAW (Бортовой с КМУ 7т) (Н 499 ОК 65) | C11: Н 499 ОК 65 | D11: ООО ФДС | SC11: 8 | SD11: 228 | SE11: П | SF11: 8 | SG11: 228 | SH11: П | SL11: 8 | SM11: 45 | SN11: Д | TP11: 8 | TQ11: 45 | TR11: М | UO11: 8 | UP11: 45 | UQ11: Д | UR11: 8 | US11: 45 | UT11: М | UU11: 8 | UV11: 42 | UW11: М | UX11: 8 | UY11: 42 | UZ11: М | VG11: 8 | VH11: 42 | VI11: М | VM11: 8 | VN11: 42 | VO11: Д | VP11: 8 | VQ11: 42 | VR11: Д | WB11: 8 | WC11: 42 | WD11: М | WE11: 8 | WF11: 42 | WG11: М | WK11: 8 | WL11: 45 | WM11: М | WN11: 8 | WO11: 45 | WP11: М | WT11: 8 | WU11: 42 | WV11: М | WW11: 8 | WX11: 42 | WY11: М | WZ11: 8 | XA11: 42 | XB11: М | XC11: 8 | XD11: 42 | XE11: М | XU11: 8 | XV11: 42 | XW11: М | AAY11: 8 | AAZ11: 42 | ABA11: М | ABB11: 8 | ABC11: 42 | ABD11: М
A12: 8 | B12: УАЗ Профи (К 054 ВК 164) | C12: К 054 ВК 164 | D12: ООО ФДС | RE12: 8 | RF12: 228 | RG12: П
A13: 9 | B13: Ford Tranzit (К 327 ЕА 164) | C13: К 327 ЕА 164 | D13: ООО ФДС
A14: 10 | B14: УАЗ Патриот (А 184 МО 164) | C14: А 184 МО 164 | D14: ООО ФДС
A15: 11 | B15: Камаз 658610-05 (Бортовой с КМУ) (К 259 ХА 164) | C15: К 259 ХА 164 | D15: ООО УТТиСТ | TY15: 8 | TZ15: 45 | UA15: М | UO15: 8 | UP15: 45 | UQ15: Д | VJ15: 8 | VK15: 45 | VL15: Д | VM15: 8 | VN15: 45 | VO15: Д | VP15: 8 | VQ15: 45 | VR15: Д | WB15: 8 | WC15: 45 | WD15: М | WE15: 8 | WF15: 45 | WG15: М | WK15: 8 | WL15: 45 | WM15: М | WN15: 8 | WO15: 45 | WP15: М | WT15: 8 | WU15: 45 | WV15: М | WW15: 8 | WX15: 42 | WY15: М | WZ15: 8 | XA15: 42 | XB15: М | XC15: 8 | XD15: 42 | XE15: М | XU15: 8 | XV15: 42 | XW15: М | XY15: 8 | XZ15: 42 | YA15: М | YB15: 8 | YC15: 42 | YD15: М | YE15: 8 | YF15: 42 | YG15: М | YQ15: 8 | YR15: 42 | YS15: М | YW15: 8 | YX15: 42 | YY15: М | YZ15: 8 | ZA15: 42 | ZB15: М | ZI15: 8 | ZJ15: 42 | ZK15: М | ZL15: 8 | ZM15: 42 | ZN15: М | ZO15: 8 | ZP15: 42 | ZQ15: М | ZR15: 8 | ZS15: 42 | ZT15: М | ZU15: 8 | ZV15: 42 | ZW15: М | AAD15: 8 | AAE15: 42 | AAF15: М | AAG15: 8 | AAH15: 42 | AAI15: М | AAM15: 8 | AAN15: 42 | AAO15: М | AAP15: 8 | AAQ15: 42 | AAR15: М | AAY15: 8 | AAZ15: 42 | ABA15: М | ABB15: 8 | ABC15: 42 | ABD15: М
A16: 12 | B16: Кран автомобильный КС-55713-4 " Галичанин" КАМАЗ (25т) (Р 552 ТО 197) | C16: Р 552 ТО 197 | D16: ООО ФДС | RE16: 8 | RF16: 228 | RG16: П | RN16: 8 | RO16: 228 | RP16: П | RQ16: 8 | RR16: 228 | RS16: П | SC16: 8 | SD16: 228 | SE16: П | SF16: 8 | SG16: 228 | SH16: П | SI16: 8 | SJ16: 228 | SK16: П | SL16: 8 | SM16: 228 | SN16: П | SU16: 8 | SV16: 228 | SW16: П | SX16: 8 | SY16: 228 | SZ16: П | TA16: 8 | TB16: 228 | TC16: П | TD16: 8 | TE16: 228 | TF16: П | TP16: 8 | TQ16: 45 | TR16: М | TS16: 8 | TT16: 45 | TU16: М | TV16: 8 | TW16: 45 | TX16: М | TY16: 8 | TZ16: 45 | UA16: М | UL16: 8 | UM16: 80 | UN16: Д | UR16: 8 | US16: 45 | UT16: М | VM16: 8 | VN16: 42 | VO16: Д | VP16: 8 | VQ16: 42 | VR16: Д | WB16: 8 | WC16: 42 | WD16: М | WE16: 8 | WF16: 42 | WG16: М | WK16: 8 | WL16: 42 | WM16: М | WN16: 8 | WO16: 42 | WP16: М | WT16: 8 | WU16: 42 | WV16: М | WW16: 8 | WX16: 42 | WY16: М | WZ16: 8 | XA16: 42 | XB16: М | XC16: 8 | XD16: 45 | XE16: М | XU16: 8 | XV16: 42 | XW16: М | XY16: 8 | XZ16: 42 | YA16: М | YB16: 8 | YC16: 42 | YD16: М | YE16: 8 | YF16: 42 | YG16: М | YQ16: 8 | YR16: 42 | YS16: М | YW16: 8 | YX16: 42 | YY16: М | YZ16: 8 | ZA16: 42 | ZB16: М | ZI16: 8 | ZJ16: 42 | ZK16: М | ZL16: 8 | ZM16: 42 | ZN16: М | ZO16: 8 | ZP16: 42 | ZQ16: М | ZR16: 8 | ZS16: 42 | ZT16: М | ZU16: 8 | ZV16: 42 | ZW16: М | AAD16: 8 | AAE16: 42 | AAF16: М | AAG16: 8 | AAH16: 42 | AAI16: М | AAM16: 8 | AAN16: 42 | AAO16: М | AAP16: 8 | AAQ16: 42 | AAR16: М | AAY16: 8 | AAZ16: 42 | ABA16: М | ABB16: 8 | ABC16: 42 | ABD16: М
A17: 13 | B17: Фронтальный погрузчик LIEBHERR (1678 РВ 64) | C17: 1678 РВ 64 | D17: ООО ФДС
A18: 14 | B18: Виброкаток Bomag BMP 8500 1,6т (0433 СЕ 64) | C18: 0433 СЕ 64 | D18: ООО ФДС
A19: 15 | B19: Кран автомобильный «Галичанин» КС 55713-5В (25т) (А 129 МО 164) | C19: А 129 МО 164 | D19: ООО УТТиСТ | RE19: 8 | RF19: 228 | RG19: П | RN19: 8 | RO19: 228 | RP19: П | RQ19: 8 | RR19: 228 | RS19: П | SI19: 8 | SJ19: 228 | SK19: П | SL19: 8 | SM19: 228 | SN19: П | SU19: 8 | SV19: 228 | SW19: П | SX19: 8 | SY19: 228 | SZ19: П | TA19: 8 | TB19: 228 | TC19: П | TD19: 8 | TE19: 228 | TF19: П | TP19: 8 | TQ19: 45 | TR19: М | TS19: 8 | TT19: 45 | TU19: М | TV19: 8 | TW19: 45 | TX19: М | TY19: 8 | TZ19: 45 | UA19: М | ABB19: 8 | ABC19: 42 | ABD19: М
A20: 16 | B20: Колесный полноворотный экскаватор (2688 РВ 64) | C20: 2688 РВ 64 | D20: ООО СССР | TY20: 8 | TZ20: 45 | UA20: П
A21: 17 | B21: ГA3 ГАЗель БИЗНЕС (Е 996 ЕН 164) | C21: Е 996 ЕН 164 | D21: ООО УТТиСТ
A22: 18 | B22: Исузу (Грузовой самосвал) (В 391 МХ 797) | C22: В 391 МХ 797 | D22: ООО ФДС
A23: 19 | B23: FAW (Бортовой с КМУ 7т) (Н 307 ОК 65) | C23: Н 307 ОК 65 | D23: ООО ФДС | SU23: 8 | SV23: 45 | SW23: Д | SX23: 8 | SY23: 45 | SZ23: Д | WN23: 8 | WO23: 45 | WP23: М | WT23: 8 | WU23: 45 | WV23: М | WW23: 8 | WX23: 42 | WY23: М | WZ23: 8 | XA23: 42 | XB23: М | XC23: 8 | XD23: 45 | XE23: М | XU23: 8 | XV23: 42 | XW23: М | XY23: 8 | XZ23: 45 | YA23: М | YB23: 8 | YC23: 45 | YD23: М | YE23: 8 | YF23: 42 | YG23: М | YQ23: 8 | YR23: 42 | YS23: М | YW23: 8 | YX23: 42 | YY23: М | YZ23: 8 | ZA23: 42 | ZB23: М | ZI23: 8 | ZJ23: 42 | ZK23: М | ZL23: 8 | ZM23: 42 | ZN23: М | ZO23: 8 | ZP23: 42 | ZQ23: М | ZR23: 8 | ZS23: 42 | ZT23: М | ZU23: 8 | ZV23: 42 | ZW23: М | AAD23: 8 | AAE23: 42 | AAF23: М | AAG23: 8 | AAH23: 42 | AAI23: М | AAM23: 8 | AAN23: 42 | AAO23: М | AAP23: 8 | AAQ23: 45 | AAR23: М | AAY23: 8 | AAZ23: 42 | ABA23: М | ABB23: 8 | ABC23: 42 | ABD23: М
A24: 20 | B24: КАМАЗ-43118-10 (Миксер) (О 285 МС 11) | C24: О 285 МС 11 | D24: ООО ФДС
A25: 21 | B25: Соболь (7 мест) (К 222 ХА 164) | C25: К 222 ХА 164 | D25: ООО УТТиСТ
A26: 22 | B26: Грузовой тягач седельный КАМАЗ 44108-RF (длиномер) (В 483 УХ 64) | C26: В 483 УХ 64 | D26: ООО УТТиСТ | RE26: 8 | RF26: 228 | RG26: П | RN26: 8 | RO26: 228 | RP26: П | RQ26: 8 | RR26: 228 | RS26: П | SC26: 8 | SD26: 228 | SE26: П | SF26: 8 | SG26: 228 | SH26: П | SI26: 8 | SJ26: 228 | SK26: П | SL26: 8 | SM26: 228 | SN26: П | SU26: 8 | SV26: 228 | SW26: П | SX26: 8 | SY26: 228 | SZ26: П | TA26: 8 | TB26: 228 | TC26: П | TD26: 8 | TE26: 228 | TF26: П
A27: 23 | B27: Камаз 658610-05 (Бортовой с КМУ) (К 280 ХА 164) | C27: К 280 ХА 164 | D27: ООО УТТиСТ
A28: 24 | B28: УАЗ Профи (К782ХН164) | C28: К782ХН164 | D28: ООО УТТиСТ
A29: 25 | B29: АУЗ Патриот (Е547ЕТ164) | C29: Е547ЕТ164 | D29: ООО УТТиСТ
A30: 26 | B30: Камаз 667-511-300 (Бортовой с КМУ) (К251ХА164) | C30: К251ХА164 | D30: ООО УТТиСТ
A31: 27 | B31: Трал (арендная техника) | C31: - | D31: - | TS31: 8 | TT31: 45 | TU31: П | TV31: 8 | TW31: 45 | TX31: П

Sheet Отчет
A1: Ключ | B1: Шифр/объект | C1: FAW (Бортовой с КМУ 7т) (Н 307 ОК 65) | D1: FAW (Бортовой с КМУ 7т) (Н 499 ОК 65) | E1: Ford Tranzit (К 327 ЕА 164) | F1: Renault Duster (Е 066 КМ 164) | G1: Автобус ПАЗ (30 мест) (К 098 ВК 164) | H1: АУЗ Патриот (Е547ЕТ164) | I1: Виброкаток Bomag BMP 8500 1,6т (0433 СЕ 64) | J1: Виброкаток Bomag BMP 8500 1,6т (6038 СМ 64) | K1: ГA3 ГАЗель БИЗНЕС (Е 996 ЕН 164) | L1: Грузовой тягач седельный КАМАЗ 44108-RF (длиномер) (В 483 УХ 64) | M1: Исузу (Грузовой самосвал) (В 391 МХ 797) | N1: Камаз 658610-05 (Бортовой с КМУ) (К 259 ХА 164) | O1: Камаз 658610-05 (Бортовой с КМУ) (К 280 ХА 164) | P1: Камаз 667-511-300 (Бортовой с КМУ) (К251ХА164) | Q1: КАМАЗ длинномер К1Е1А6 с КМУ (Х 726 СХ 797) | R1: КАМАЗ-43118-10 (Миксер) (О 285 МС 11) | S1: Колесный полноворотный экскаватор (2688 РВ 64) | T1: Кран автомобильный «Галичанин» КС 55713-5В (25т) (А 129 МО 164) | U1: Кран автомобильный КС-55713-4 " Галичанин" КАМАЗ (25т) (Р 552 ТО 197) | V1: МАЗ 6501В9-8420-000 (Грузовой самосвал) (А 347 ЕМ 164) | W1: Соболь (7 мест) (К 222 ХА 164) | X1: УАЗ Патриот (А 184 МО 164) | Y1: УАЗ Профи (К 054 ВК 164) | Z1: УАЗ Профи (К782ХН164) | AA1: Фронтальный погрузчик LIEBHERR (1678 РВ 64) | AB1: Экскаватор погрузчик JCB (0634 АА 64)
A2: Ключ | C2: =MATCH(C$1,Техника!$B$1:$B$31,0) -> 23 | D2: =MATCH(D$1,Техника!$B$1:$B$31,0) -> 11 | E2: =MATCH(E$1,Техника!$B$1:$B$31,0) -> 13 | F2: =MATCH(F$1,Техника!$B$1:$B$31,0) -> 5 | G2: =MATCH(G$1,Техника!$B$1:$B$31,0) -> 8 | H2: =MATCH(H$1,Техника!$B$1:$B$31,0) -> 29 | I2: =MATCH(I$1,Техника!$B$1:$B$31,0) -> 18 | J2: =MATCH(J$1,Техника!$B$1:$B$31,0) -> 10 | ... AB2: =MATCH(AB$1,Техника!$B$1:$B$31,0) -> 7
A3: Отработано часов: | C3: =SUMPRODUCT(ISNUMBER($A$5:$A$1622)*C$5:C$1622) -> 200 | D3: =SUMPRODUCT(ISNUMBER($A$5:$A$1622)*D$5:D$1622) -> 176 | E3: =SUMPRODUCT(ISNUMBER($A$5:$A$1622)*E$5:E$1622) -> 0 | F3: =SUMPRODUCT(ISNUMBER($A$5:$A$1622)*F$5:F$1622) -> 0 | G3: =SUMPRODUCT(ISNUMBER($A$5:$A$1622)*G$5:G$1622) -> 0 | H3: =SUMPRODUCT(ISNUMBER($A$5:$A$1622)*H$5:H$1622) -> 0 | I3: =SUMPRODUCT(ISNUMBER($A$5:$A$1622)*I$5:I$1622) -> 0 | J3: =SUMPRODUCT(ISNUMBER($A$5:$A$1622)*J$5:J$1622) -> 0 | ... AB3: =SUMPRODUCT(ISNUMBER($A$5:$A$1622)*AB$5:AB$1622) -> 0
A4: 1 | B4: 4214.00.П.04.ГРП.004.000.ВК. | C4: =SUM(C5:C9) -> 0 | D4: =SUM(D5:D9) -> 0 | E4: =SUM(E5:E9) -> 0 | F4: =SUM(F5:F9) -> 0 | G4: =SUM(G5:G9) -> 0 | H4: =SUM(H5:H9) -> 0 | I4: =SUM(I5:I9) -> 0 | J4: =SUM(J5:J9) -> 0 | ... AB4: =SUM(AB5:AB9) -> 0
A5: М | B5: Монтажные работы | C5: =SUMIFS(INDEX(Техника!$F$1:$ABM$500,C$2,0),Техника!$F$4:$ABM$4,"Часы",INDEX(Техника!$G$1:$ABN$500,C$2,0),$A$4,INDEX(Техника!$H$1:$ABO$500,C$2,0),"М") -> 0 | D5: =SUMIFS(INDEX(Техника!$F$1:$ABM$500,D$2,0),Техника!$F$4:$ABM$4,"Часы",INDEX(Техника!$G$1:$ABN$500,D$2,0),$A$4,INDEX(Техника!$H$1:$ABO$500,D$2,0),"М") -> 0 | E5: =SUMIFS(INDEX(Техника!$F$1:$ABM$500,E$2,0),Техника!$F$4:$ABM$4,"Часы",INDEX(Техника!$G$1:$ABN$500,E$2,0),$A$4,INDEX(Техника!$H$1:$ABO$500,E$2,0),"М") -> 0 | F5: =SUMIFS(INDEX(Техника!$F$1:$ABM$500,F$2,0),Техника!$F$4:$ABM$4,"Часы",INDEX(Техника!$G$1:$ABN$500,F$2,0),$A$4,INDEX(Техника!$H$1:$ABO$500,F$2,0),"М") -> 0 | G5: =SUMIFS(INDEX(Техника!$F$1:$ABM$500,G$2,0),Техника!$F$4:$ABM$4,"Часы",INDEX(Техника!$G$1:$ABN$500,G$2,0),$A$4,INDEX(Техника!$H$1:$ABO$500,G$2,0),"М") -> 0 | H5: =SUMIFS(INDEX(Техника!$F$1:$ABM$500,H$2,0),Техника!$F$4:$ABM$4,"Часы",INDEX(Техника!$G$1:$ABN$500,H$2,0),$A$4,INDEX(Техника!$H$1:$ABO$500,H$2,0),"М") -> 0 | I5: =SUMIFS(INDEX(Техника!$F$1:$ABM$500,I$2,0),Техника!$F$4:$ABM$4,"Часы",INDEX(Техника!$G$1:$ABN$500,I$2,0),$A$4,INDEX(Техника!$H$1:$ABO$500,I$2,0),"М") -> 0 | J5: =SUMIFS(INDEX(Техника!$F$1:$ABM$500,J$2,0),Техника!$F$4:$ABM$4,"Часы",INDEX(Техника!$G$1:$ABN$500,J$2,0),$A$4,INDEX(Техника!$H$1:$ABO$500,J$2,0),"М") -> 0 | ... AB5: =SUMIFS(INDEX(Техника!$F$1:$ABM$500,AB$2,0),Техника!$F$4:$ABM$4,"Часы",INDEX(Техника!$G$1:$ABN$500,AB$2,0),$A$4,INDEX(Техника!$H$1:$ABO$500,AB$2,0),"М") -> 0
A6: Д | B6: Демонтажные работы | C6: =SUMIFS(INDEX(Техника!$F$1:$ABM$500,C$2,0),Техника!$F$4:$ABM$4,"Часы",INDEX(Техника!$G$1:$ABN$500,C$2,0),$A$4,INDEX(Техника!$H$1:$ABO$500,C$2,0),"Д") -> 0 | D6: =SUMIFS(INDEX(Техника!$F$1:$ABM$500,D$2,0),Техника!$F$4:$ABM$4,"Часы",INDEX(Техника!$G$1:$ABN$500,D$2,0),$A$4,INDEX(Техника!$H$1:$ABO$500,D$2,0),"Д") -> 0 | E6: =SUMIFS(INDEX(Техника!$F$1:$ABM$500,E$2,0),Техника!$F$4:$ABM$4,"Часы",INDEX(Техника!$G$1:$ABN$500,E$2,0),$A$4,INDEX(Техника!$H$1:$ABO$500,E$2,0),"Д") -> 0 | F6: =SUMIFS(INDEX(Техника!$F$1:$ABM$500,F$2,0),Техника!$F$4:$ABM$4,"Часы",INDEX(Техника!$G$1:$ABN$500,F$2,0),$A$4,INDEX(Техника!$H$1:$ABO$500,F$2,0),"Д") -> 0 | G6: =SUMIFS(INDEX(Техника!$F$1:$ABM$500,G$2,0),Техника!$F$4:$ABM$4,"Часы",INDEX(Техника!$G$1:$ABN$500,G$2,0),$A$4,INDEX(Техника!$H$1:$ABO$500,G$2,0),"Д") -> 0 | H6: =SUMIFS(INDEX(Техника!$F$1:$ABM$500,H$2,0),Техника!$F$4:$ABM$4,"Часы",INDEX(Техника!$G$1:$ABN$500,H$2,0),$A$4,INDEX(Техника!$H$1:$ABO$500,H$2,0),"Д") -> 0 | I6: =SUMIFS(INDEX(Техника!$F$1:$ABM$500,I$2,0),Техника!$F$4:$ABM$4,"Часы",INDEX(Техника!$G$1:$ABN$500,I$2,0),$A$4,INDEX(Техника!$H$1:$ABO$500,I$2,0),"Д") -> 0 | J6: =SUMIFS(INDEX(Техника!$F$1:$ABM$500,J$2,0),Техника!$F$4:$ABM$4,"Часы",INDEX(Техника!$G$1:$ABN$500,J$2,0),$A$4,INDEX(Техника!$H$1:$ABO$500,J$2,0),"Д") -> 0 | ... AB6: =SUMIFS(INDEX(Техника!$F$1:$ABM$500,AB$2,0),Техника!$F$4:$ABM$4,"Часы",INDEX(Техника!$G$1:$ABN$500,AB$2,0),$A$4,INDEX(Техника!$H$1:$ABO$500,AB$2,0),"Д") -> 0
A7: П | B7: Погрузка, перевозка | C7: =SUMIFS(INDEX(Техника!$F$1:$ABM$500,C$2,0),Техника!$F$4:$ABM$4,"Часы",INDEX(Техника!$G$1:$ABN$500,C$2,0),$A$4,INDEX(Техника!$H$1:$ABO$500,C$2,0),"П") -> 0 | D7: =SUMIFS(INDEX(Техника!$F$1:$ABM$500,D$2,0),Техника!$F$4:$ABM$4,"Часы",INDEX(Техника!$G$1:$ABN$500,D$2,0),$A$4,INDEX(Техника!$H$1:$ABO$500,D$2,0),"П") -> 0 | E7: =SUMIFS(INDEX(Техника!$F$1:$ABM$500,E$2,0),Техника!$F$4:$ABM$4,"Часы",INDEX(Техника!$G$1:$ABN$500,E$2,0),$A$4,INDEX(Техника!$H$1:$ABO$500,E$2,0),"П") -> 0 | F7: =SUMIFS(INDEX(Техника!$F$1:$ABM$500,F$2,0),Техника!$F$4:$ABM$4,"Часы",INDEX(Техника!$G$1:$ABN$500,F$2,0),$A$4,INDEX(Техника!$H$1:$ABO$500,F$2,0),"П") -> 0 | G7: =SUMIFS(INDEX(Техника!$F$1:$ABM$500,G$2,0),Техника!$F$4:$ABM$4,"Часы",INDEX(Техника!$G$1:$ABN$500,G$2,0),$A$4,INDEX(Техника!$H$1:$ABO$500,G$2,0),"П") -> 0 | H7: =SUMIFS(INDEX(Техника!$F$1:$ABM$500,H$2,0),Техника!$F$4:$ABM$4,"Часы",INDEX(Техника!$G$1:$ABN$500,H$2,0),$A$4,INDEX(Техника!$H$1:$ABO$500,H$2,0),"П") -> 0 | I7: =SUMIFS(INDEX(Техника!$F$1:$ABM$500,I$2,0),Техника!$F$4:$ABM$4,"Часы",INDEX(Техника!$G$1:$ABN$500,I$2,0),$A$4,INDEX(Техника!$H$1:$ABO$500,I$2,0),"П") -> 0 | J7: =SUMIFS(INDEX(Техника!$F$1:$ABM$500,J$2,0),Техника!$F$4:$ABM$4,"Часы",INDEX(Техника!$G$1:$ABN$500,J$2,0),$A$4,INDEX(Техника!$H$1:$ABO$500,J$2,0),"П") -> 0 | ... AB7: =SUMIFS(INDEX(Техника!$F$1:$ABM$500,AB$2,0),Техника!$F$4:$ABM$4,"Часы",INDEX(Техника!$G$1:$ABN$500,AB$2,0),$A$4,INDEX(Техника!$H$1:$ABO$500,AB$2,0),"П") -> 0
A8: Л | B8: Перевозка людей | C8: =SUMIFS(INDEX(Техника!$F$1:$ABM$500,C$2,0),Техника!$F$4:$ABM$4,"Часы",INDEX(Техника!$G$1:$ABN$500,C$2,0),$A$4,INDEX(Техника!$H$1:$ABO$500,C$2,0),"Л") -> 0 | D8: =SUMIFS(INDEX(Техника!$F$1:$ABM$500,D$2,0),Техника!$F$4:$ABM$4,"Часы",INDEX(Техника!$G$1:$ABN$500,D$2,0),$A$4,INDEX(Техника!$H$1:$ABO$500,D$2,0),"Л") -> 0 | E8: =SUMIFS(INDEX(Техника!$F$1:$ABM$500,E$2,0),Техника!$F$4:$ABM$4,"Часы",INDEX(Техника!$G$1:$ABN$500,E$2,0),$A$4,INDEX(Техника!$H$1:$ABO$500,E$2,0),"Л") -> 0 | F8: =SUMIFS(INDEX(Техника!$F$1:$ABM$500,F$2,0),Техника!$F$4:$ABM$4,"Часы",INDEX(Техника!$G$1:$ABN$500,F$2,0),$A$4,INDEX(Техника!$H$1:$ABO$500,F$2,0),"Л") -> 0 | G8: =SUMIFS(INDEX(Техника!$F$1:$ABM$500,G$2,0),Техника!$F$4:$ABM$4,"Часы",INDEX(Техника!$G$1:$ABN$500,G$2,0),$A$4,INDEX(Техника!$H$1:$ABO$500,G$2,0),"Л") -> 0 | H8: =SUMIFS(INDEX(Техника!$F$1:$ABM$500,H$2,0),Техника!$F$4:$ABM$4,"Часы",INDEX(Техника!$G$1:$ABN$500,H$2,0),$A$4,INDEX(Техника!$H$1:$ABO$500,H$2,0),"Л") -> 0 | I8: =SUMIFS(INDEX(Техника!$F$1:$ABM$500,I$2,0),Техника!$F$4:$ABM$4,"Часы",INDEX(Техника!$G$1:$ABN$500,I$2,0),$A$4,INDEX(Техника!$H$1:$ABO$500,I$2,0),"Л") -> 0 | J8: =SUMIFS(INDEX(Техника!$F$1:$ABM$500,J$2,0),Техника!$F$4:$ABM$4,"Часы",INDEX(Техника!$G$1:$ABN$500,J$2,0),$A$4,INDEX(Техника!$H$1:$ABO$500,J$2,0),"Л") -> 0 | ... AB8: =SUMIFS(INDEX(Техника!$F$1:$ABM$500,AB$2,0),Техника!$F$4:$ABM$4,"Часы",INDEX(Техника!$G$1:$ABN$500,AB$2,0),$A$4,INDEX(Техника!$H$1:$ABO$500,AB$2,0),"Л") -> 0
A9: З | B9: Земляные работы | C9: =SUMIFS(INDEX(Техника!$F$1:$ABM$500,C$2,0),Техника!$F$4:$ABM$4,"Часы",INDEX(Техника!$G$1:$ABN$500,C$2,0),$A$4,INDEX(Техника!$H$1:$ABO$500,C$2,0),"З") -> 0 | D9: =SUMIFS(INDEX(Техника!$F$1:$ABM$500,D$2,0),Техника!$F$4:$ABM$4,"Часы",INDEX(Техника!$G$1:$ABN$500,D$2,0),$A$4,INDEX(Техника!$H$1:$ABO$500,D$2,0),"З") -> 0 | E9: =SUMIFS(INDEX(Техника!$F$1:$ABM$500,E$2,0),Техника!$F$4:$ABM$4,"Часы",INDEX(Техника!$G$1:$ABN$500,E$2,0),$A$4,INDEX(Техника!$H$1:$ABO$500,E$2,0),"З") -> 0 | F9: =SUMIFS(INDEX(Техника!$F$1:$ABM$500,F$2,0),Техника!$F$4:$ABM$4,"Часы",INDEX(Техника!$G$1:$ABN$500,F$2,0),$A$4,INDEX(Техника!$H$1:$ABO$500,F$2,0),"З") -> 0 | G9: =SUMIFS(INDEX(Техника!$F$1:$ABM$500,G$2,0),Техника!$F$4:$ABM$4,"Часы",INDEX(Техника!$G$1:$ABN$500,G$2,0),$A$4,INDEX(Техника!$H$1:$ABO$500,G$2,0),"З") -> 0 | H9: =SUMIFS(INDEX(Техника!$F$1:$ABM$500,H$2,0),Техника!$F$4:$ABM$4,"Часы",INDEX(Техника!$G$1:$ABN$500,H$2,0),$A$4,INDEX(Техника!$H$1:$ABO$500,H$2,0),"З") -> 0 | I9: =SUMIFS(INDEX(Техника!$F$1:$ABM$500,I$2,0),Техника!$F$4:$ABM$4,"Часы",INDEX(Техника!$G$1:$ABN$500,I$2,0),$A$4,INDEX(Техника!$H$1:$ABO$500,I$2,0),"З") -> 0 | J9: =SUMIFS(INDEX(Техника!$F$1:$ABM$500,J$2,0),Техника!$F$4:$ABM$4,"Часы",INDEX(Техника!$G$1:$ABN$500,J$2,0),$A$4,INDEX(Техника!$H$1:$ABO$500,J$2,0),"З") -> 0 | ... AB9: =SUMIFS(INDEX(Техника!$F$1:$ABM$500,AB$2,0),Техника!$F$4:$ABM$4,"Часы",INDEX(Техника!$G$1:$ABN$500,AB$2,0),$A$4,INDEX(Техника!$H$1:$ABO$500,AB$2,0),"З") -> 0
A11: 2 | B11: 4214.00.П.04.ГРП.004.000.Т. | C11: =SUM(C12:C16) -> 0 | D11: =SUM(D12:D16) -> 0 | E11: =SUM(E12:E16) -> 0 | F11: =SUM(F12:F16) -> 0 | G11: =SUM(G12:G16) -> 0 | H11: =SUM(H12:H16) -> 0 | I11: =SUM(I12:I16) -> 0 | J11: =SUM(J12:J16) -> 0 | ... AB11: =SUM(AB12:AB16) -> 0
A12: М | B12: Монтажные работы | C12: =SUMIFS(INDEX(Техника!$F$1:$ABM$500,C$2,0),Техника!$F$4:$ABM$4,"Часы",INDEX(Техника!$G$1:$ABN$500,C$2,0),$A$11,INDEX(Техника!$H$1:$ABO$500,C$2,0),"М") -> 0 | D12: =SUMIFS(INDEX(Техника!$F$1:$ABM$500,D$2,0),Техника!$F$4:$ABM$4,"Часы",INDEX(Техника!$G$1:$ABN$500,D$2,0),$A$11,INDEX(Техника!$H$1:$ABO$500,D$2,0),"М") -> 0 | E12: =SUMIFS(INDEX(Техника!$F$1:$ABM$500,E$2,0),Техника!$F$4:$ABM$4,"Часы",INDEX(Техника!$G$1:$ABN$500,E$2,0),$A$11,INDEX(Техника!$H$1:$ABO$500,E$2,0),"М") -> 0 | F12: =SUMIFS(INDEX(Техника!$F$1:$ABM$500,F$2,0),Техника!$F$4:$ABM$4,"Часы",INDEX(Техника!$G$1:$ABN$500,F$2,0),$A$11,INDEX(Техника!$H$1:$ABO$500,F$2,0),"М") -> 0 | G12: =SUMIFS(INDEX(Техника!$F$1:$ABM$500,G$2,0),Техника!$F$4:$ABM$4,"Часы",INDEX(Техника!$G$1:$ABN$500,G$2,0),$A$11,INDEX(Техника!$H$1:$ABO$500,G$2,0),"М") -> 0 | H12: =SUMIFS(INDEX(Техника!$F$1:$ABM$500,H$2,0),Техника!$F$4:$ABM$4,"Часы",INDEX(Техника!$G$1:$ABN$500,H$2,0),$A$11,INDEX(Техника!$H$1:$ABO$500,H$2,0),"М") -> 0 | I12: =SUMIFS(INDEX(Техника!$F$1:$ABM$500,I$2,0),Техника!$F$4:$ABM$4,"Часы",INDEX(Техника!$G$1:$ABN$500,I$2,0),$A$11,INDEX(Техника!$H$1:$ABO$500,I$2,0),"М") -> 0 | J12: =SUMIFS(INDEX(Техника!$F$1:$ABM$500,J$2,0),Техника!$F$4:$ABM$4,"Часы",INDEX(Техника!$G$1:$ABN$500,J$2,0),$A$11,INDEX(Техника!$H$1:$ABO$500,J$2,0),"М") -> 0 | ... AB12: =SUMIFS(INDEX(Техника!$F$1:$ABM$500,AB$2,0),Техника!$F$4:$ABM$4,"Часы",INDEX(Техника!$G$1:$ABN$500,AB$2,0),$A$11,INDEX(Техника!$H$1:$ABO$500,AB$2,0),"М") -> 0
A13: Д | B13: Демонтажные работы | C13: =SUMIFS(INDEX(Техника!$F$1:$ABM$500,C$2,0),Техника!$F$4:$ABM$4,"Часы",INDEX(Техника!$G$1:$ABN$500,C$2,0),$A$11,INDEX(Техника!$H$1:$ABO$500,C$2,0),"Д") -> 0 | D13: =SUMIFS(INDEX(Техника!$F$1:$ABM$500,D$2,0),Техника!$F$4:$ABM$4,"Часы",INDEX(Техника!$G$1:$ABN$500,D$2,0),$A$11,INDEX(Техника!$H$1:$ABO$500,D$2,0),"Д") -> 0 | E13: =SUMIFS(INDEX(Техника!$F$1:$ABM$500,E$2,0),Техника!$F$4:$ABM$4,"Часы",INDEX(Техника!$G$1:$ABN$500,E$2,0),$A$11,INDEX(Техника!$H$1:$ABO$500,E$2,0),"Д") -> 0 | F13: =SUMIFS(INDEX(Техника!$F$1:$ABM$500,F$2,0),Техника!$F$4:$ABM$4,"Часы",INDEX(Техника!$G$1:$ABN$500,F$2,0),$A$11,INDEX(Техника!$H$1:$ABO$500,F$2,0),"Д") -> 0 | G13: =SUMIFS(INDEX(Техника!$F$1:$ABM$500,G$2,0),Техника!$F$4:$ABM$4,"Часы",INDEX(Техника!$G$1:$ABN$500,G$2,0),$A$11,INDEX(Техника!$H$1:$ABO$500,G$2,0),"Д") -> 0 | H13: =SUMIFS(INDEX(Техника!$F$1:$ABM$500,H$2,0),Техника!$F$4:$ABM$4,"Часы",INDEX(Техника!$G$1:$ABN$500,H$2,0),$A$11,INDEX(Техника!$H$1:$ABO$500,H$2,0),"Д") -> 0 | I13: =SUMIFS(INDEX(Техника!$F$1:$ABM$500,I$2,0),Техника!$F$4:$ABM$4,"Часы",INDEX(Техника!$G$1:$ABN$500,I$2,0),$A$11,INDEX(Техника!$H$1:$ABO$500,I$2,0),"Д") -> 0 | J13: =SUMIFS(INDEX(Техника!$F$1:$ABM$500,J$2,0),Техника!$F$4:$ABM$4,"Часы",INDEX(Техника!$G$1:$ABN$500,J$2,0),$A$11,INDEX(Техника!$H$1:$ABO$500,J$2,0),"Д") -> 0 | ... AB13: =SUMIFS(INDEX(Техника!$F$1:$ABM$500,AB$2,0),Техника!$F$4:$ABM$4,"Часы",INDEX(Техника!$G$1:$ABN$500,AB$2,0),$A$11,INDEX(Техника!$H$1:$ABO$500,AB$2,0),"Д") -> 0
A14: П | B14: Погрузка, перевозка | C14: =SUMIFS(INDEX(Техника!$F$1:$ABM$500,C$2,0),Техника!$F$4:$ABM$4,"Часы",INDEX(Техника!$G$1:$ABN$500,C$2,0),$A$11,INDEX(Техника!$H$1:$ABO$500,C$2,0),"П") -> 0 | D14: =SUMIFS(INDEX(Техника!$F$1:$ABM$500,D$2,0),Техника!$F$4:$ABM$4,"Часы",INDEX(Техника!$G$1:$ABN$500,D$2,0),$A$11,INDEX(Техника!$H$1:$ABO$500,D$2,0),"П") -> 0 | E14: =SUMIFS(INDEX(Техника!$F$1:$ABM$500,E$2,0),Техника!$F$4:$ABM$4,"Часы",INDEX(Техника!$G$1:$ABN$500,E$2,0),$A$11,INDEX(Техника!$H$1:$ABO$500,E$2,0),"П") -> 0 | F14: =SUMIFS(INDEX(Техника!$F$1:$ABM$500,F$2,0),Техника!$F$4:$ABM$4,"Часы",INDEX(Техника!$G$1:$ABN$500,F$2,0),$A$11,INDEX(Техника!$H$1:$ABO$500,F$2,0),"П") -> 0 | G14: =SUMIFS(INDEX(Техника!$F$1:$ABM$500,G$2,0),Техника!$F$4:$ABM$4,"Часы",INDEX(Техника!$G$1:$ABN$500,G$2,0),$A$11,INDEX(Техника!$H$1:$ABO$500,G$2,0),"П") -> 0 | H14: =SUMIFS(INDEX(Техника!$F$1:$ABM$500,H$2,0),Техника!$F$4:$ABM$4,"Часы",INDEX(Техника!$G$1:$ABN$500,H$2,0),$A$11,INDEX(Техника!$H$1:$ABO$500,H$2,0),"П") -> 0 | I14: =SUMIFS(INDEX(Техника!$F$1:$ABM$500,I$2,0),Техника!$F$4:$ABM$4,"Часы",INDEX(Техника!$G$1:$ABN$500,I$2,0),$A$11,INDEX(Техника!$H$1:$ABO$500,I$2,0),"П") -> 0 | J14: =SUMIFS(INDEX(Техника!$F$1:$ABM$500,J$2,0),Техника!$F$4:$ABM$4,"Часы",INDEX(Техника!$G$1:$ABN$500,J$2,0),$A$11,INDEX(Техника!$H$1:$ABO$500,J$2,0),"П") -> 0 | ... AB14: =SUMIFS(INDEX(Техника!$F$1:$ABM$500,AB$2,0),Техника!$F$4:$ABM$4,"Часы",INDEX(Техника!$G$1:$ABN$500,AB$2,0),$A$11,INDEX(Техника!$H$1:$ABO$500,AB$2,0),"П") -> 0
A15: Л | B15: Перевозка людей | C15: =SUMIFS(INDEX(Техника!$F$1:$ABM$500,C$2,0),Техника!$F$4:$ABM$4,"Часы",INDEX(Техника!$G$1:$ABN$500,C$2,0),$A$11,INDEX(Техника!$H$1:$ABO$500,C$2,0),"Л") -> 0 | D15: =SUMIFS(INDEX(Техника!$F$1:$ABM$500,D$2,0),Техника!$F$4:$ABM$4,"Часы",INDEX(Техника!$G$1:$ABN$500,D$2,0),$A$11,INDEX(Техника!$H$1:$ABO$500,D$2,0),"Л") -> 0 | E15: =SUMIFS(INDEX(Техника!$F$1:$ABM$500,E$2,0),Техника!$F$4:$ABM$4,"Часы",INDEX(Техника!$G$1:$ABN$500,E$2,0),$A$11,INDEX(Техника!$H$1:$ABO$500,E$2,0),"Л") -> 0 | F15: =SUMIFS(INDEX(Техника!$F$1:$ABM$500,F$2,0),Техника!$F$4:$ABM$4,"Часы",INDEX(Техника!$G$1:$ABN$500,F$2,0),$A$11,INDEX(Техника!$H$1:$ABO$500,F$2,0),"Л") -> 0 | G15: =SUMIFS(INDEX(Техника!$F$1:$ABM$500,G$2,0),Техника!$F$4:$ABM$4,"Часы",INDEX(Техника!$G$1:$ABN$500,G$2,0),$A$11,INDEX(Техника!$H$1:$ABO$500,G$2,0),"Л") -> 0 | H15: =SUMIFS(INDEX(Техника!$F$1:$ABM$500,H$2,0),Техника!$F$4:$ABM$4,"Часы",INDEX(Техника!$G$1:$ABN$500,H$2,0),$A$11,INDEX(Техника!$H$1:$ABO$500,H$2,0),"Л") -> 0 | I15: =SUMIFS(INDEX(Техника!$F$1:$ABM$500,I$2,0),Техника!$F$4:$ABM$4,"Часы",INDEX(Техника!$G$1:$ABN$500,I$2,0),$A$11,INDEX(Техника!$H$1:$ABO$500,I$2,0),"Л") -> 0 | J15: =SUMIFS(INDEX(Техника!$F$1:$ABM$500,J$2,0),Техника!$F$4:$ABM$4,"Часы",INDEX(Техника!$G$1:$ABN$500,J$2,0),$A$11,INDEX(Техника!$H$1:$ABO$500,J$2,0),"Л") -> 0 | ... AB15: =SUMIFS(INDEX(Техника!$F$1:$ABM$500,AB$2,0),Техника!$F$4:$ABM$4,"Часы",INDEX(Техника!$G$1:$ABN$500,AB$2,0),$A$11,INDEX(Техника!$H$1:$ABO$500,AB$2,0),"Л") -> 0
A16: З | B16: Земляные работы | C16: =SUMIFS(INDEX(Техника!$F$1:$ABM$500,C$2,0),Техника!$F$4:$ABM$4,"Часы",INDEX(Техника!$G$1:$ABN$500,C$2,0),$A$11,INDEX(Техника!$H$1:$ABO$500,C$2,0),"З") -> 0 | D16: =SUMIFS(INDEX(Техника!$F$1:$ABM$500,D$2,0),Техника!$F$4:$ABM$4,"Часы",INDEX(Техника!$G$1:$ABN$500,D$2,0),$A$11,INDEX(Техника!$H$1:$ABO$500,D$2,0),"З") -> 0 | E16: =SUMIFS(INDEX(Техника!$F$1:$ABM$500,E$2,0),Техника!$F$4:$ABM$4,"Часы",INDEX(Техника!$G$1:$ABN$500,E$2,0),$A$11,INDEX(Техника!$H$1:$ABO$500,E$2,0),"З") -> 0 | F16: =SUMIFS(INDEX(Техника!$F$1:$ABM$500,F$2,0),Техника!$F$4:$ABM$4,"Часы",INDEX(Техника!$G$1:$ABN$500,F$2,0),$A$11,INDEX(Техника!$H$1:$ABO$500,F$2,0),"З") -> 0 | G16: =SUMIFS(INDEX(Техника!$F$1:$ABM$500,G$2,0),Техника!$F$4:$ABM$4,"Часы",INDEX(Техника!$G$1:$ABN$500,G$2,0),$A$11,INDEX(Техника!$H$1:$ABO$500,G$2,0),"З") -> 0 | H16: =SUMIFS(INDEX(Техника!$F$1:$ABM$500,H$2,0),Техника!$F$4:$ABM$4,"Часы",INDEX(Техника!$G$1:$ABN$500,H$2,0),$A$11,INDEX(Техника!$H$1:$ABO$500,H$2,0),"З") -> 0 | I16: =SUMIFS(INDEX(Техника!$F$1:$ABM$500,I$2,0),Техника!$F$4:$ABM$4,"Часы",INDEX(Техника!$G$1:$ABN$500,I$2,0),$A$11,INDEX(Техника!$H$1:$ABO$500,I$2,0),"З") -> 0 | J16: =SUMIFS(INDEX(Техника!$F$1:$ABM$500,J$2,0),Техника!$F$4:$ABM$4,"Часы",INDEX(Техника!$G$1:$ABN$500,J$2,0),$A$11,INDEX(Техника!$H$1:$ABO$500,J$2,0),"З") -> 0 | ... AB16: =SUMIFS(INDEX(Техника!$F$1:$ABM$500,AB$2,0),Техника!$F$4:$ABM$4,"Часы",INDEX(Техника!$G$1:$ABN$500,AB$2,0),$A$11,INDEX(Техника!$H$1:$ABO$500,AB$2,0),"З") -> 0
A18: 3 | B18: 4214.00.П.04.ГРП.004.003.АС | C18: =SUM(C19:C23) -> 0 | D18: =SUM(D19:D23) -> 0 | E18: =SUM(E19:E23) -> 0 | F18: =SUM(F19:F23) -> 0 | G18: =SUM(G19:G23) -> 0 | H18: =SUM(H19:H23) -> 0 | I18: =SUM(I19:I23) -> 0 | J18: =SUM(J19:J23) -> 0 | ... AB18: =SUM(AB19:AB23) -> 0
A19: М | B19: Монтажные работы | C19: =SUMIFS(INDEX(Техника!$F$1:$ABM$500,C$2,0),Техника!$F$4:$ABM$4,"Часы",INDEX(Техника!$G$1:$ABN$500,C$2,0),$A$18,INDEX(Техника!$H$1:$ABO$500,C$2,0),"М") -> 0 | D19: =SUMIFS(INDEX(Техника!$F$1:$ABM$500,D$2,0),Техника!$F$4:$ABM$4,"Часы",INDEX(Техника!$G$1:$ABN$500,D$2,0),$A$18,INDEX(Техника!$H$1:$ABO$500,D$2,0),"М") -> 0 | E19: =SUMIFS(INDEX(Техника!$F$1:$ABM$500,E$2,0),Техника!$F$4:$ABM$4,"Часы",INDEX(Техника!$G$1:$ABN$500,E$2,0),$A$18,INDEX(Техника!$H$1:$ABO$500,E$2,0),"М") -> 0 | F19: =SUMIFS(INDEX(Техника!$F$1:$ABM$500,F$2,0),Техника!$F$4:$ABM$4,"Часы",INDEX(Техника!$G$1:$ABN$500,F$2,0),$A$18,INDEX(Техника!$H$1:$ABO$500,F$2,0),"М") -> 0 | G19: =SUMIFS(INDEX(Техника!$F$1:$ABM$500,G$2,0),Техника!$F$4:$ABM$4,"Часы",INDEX(Техника!$G$1:$ABN$500,G$2,0),$A$18,INDEX(Техника!$H$1:$ABO$500,G$2,0),"М") -> 0 | H19: =SUMIFS(INDEX(Техника!$F$1:$ABM$500,H$2,0),Техника!$F$4:$ABM$4,"Часы",INDEX(Техника!$G$1:$ABN$500,H$2,0),$A$18,INDEX(Техника!$H$1:$ABO$500,H$2,0),"М") -> 0 | I19: =SUMIFS(INDEX(Техника!$F$1:$ABM$500,I$2,0),Техника!$F$4:$ABM$4,"Часы",INDEX(Техника!$G$1:$ABN$500,I$2,0),$A$18,INDEX(Техника!$H$1:$ABO$500,I$2,0),"М") -> 0 | J19: =SUMIFS(INDEX(Техника!$F$1:$ABM$500,J$2,0),Техника!$F$4:$ABM$4,"Часы",INDEX(Техника!$G$1:$ABN$500,J$2,0),$A$18,INDEX(Техника!$H$1:$ABO$500,J$2,0),"М") -> 0 | ... AB19: =SUMIFS(INDEX(Техника!$F$1:$ABM$500,AB$2,0),Техника!$F$4:$ABM$4,"Часы",INDEX(Техника!$G$1:$ABN$500,AB$2,0),$A$18,INDEX(Техника!$H$1:$ABO$500,AB$2,0),"М") -> 0
A20: Д | B20: Демонтажные работы | C20: =SUMIFS(INDEX(Техника!$F$1:$ABM$500,C$2,0),Техника!$F$4:$ABM$4,"Часы",INDEX(Техника!$G$1:$ABN$500,C$2,0),$A$18,INDEX(Техника!$H$1:$ABO$500,C$2,0),"Д") -> 0 | D20: =SUMIFS(INDEX(Техника!$F$1:$ABM$500,D$2,0),Техника!$F$4:$ABM$4,"Часы",INDEX(Техника!$G$1:$ABN$500,D$2,0),$A$18,INDEX(Техника!$H$1:$ABO$500,D$2,0),"Д") -> 0 | E20: =SUMIFS(INDEX(Техника!$F$1:$ABM$500,E$2,0),Техника!$F$4:$ABM$4,"Часы",INDEX(Техника!$G$1:$ABN$500,E$2,0),$A$18,INDEX(Техника!$H$1:$ABO$500,E$2,0),"Д") -> 0 | F20: =SUMIFS(INDEX(Техника!$F$1:$ABM$500,F$2,0),Техника!$F$4:$ABM$4,"Часы",INDEX(Техника!$G$1:$ABN$500,F$2,0),$A$18,INDEX(Техника!$H$1:$ABO$500,F$2,0),"Д") -> 0 | G20: =SUMIFS(INDEX(Техника!$F$1:$ABM$500,G$2,0),Техника!$F$4:$ABM$4,"Часы",INDEX(Техника!$G$1:$ABN$500,G$2,0),$A$18,INDEX(Техника!$H$1:$ABO$500,G$2,0),"Д") -> 0 | H20: =SUMIFS(INDEX(Техника!$F$1:$ABM$500,H$2,0),Техника!$F$4:$ABM$4,"Часы",INDEX(Техника!$G$1:$ABN$500,H$2,0),$A$18,INDEX(Техника!$H$1:$ABO$500,H$2,0),"Д") -> 0 | I20: =SUMIFS(INDEX(Техника!$F$1:$ABM$500,I$2,0),Техника!$F$4:$ABM$4,"Часы",INDEX(Техника!$G$1:$ABN$500,I$2,0),$A$18,INDEX(Техника!$H$1:$ABO$500,I$2,0),"Д") -> 0 | J20: =SUMIFS(INDEX(Техника!$F$1:$ABM$500,J$2,0),Техника!$F$4:$ABM$4,"Часы",INDEX(Техника!$G$1:$ABN$500,J$2,0),$A$18,INDEX(Техника!$H$1:$ABO$500,J$2,0),"Д") -> 0 | ... AB20: =SUMIFS(INDEX(Техника!$F$1:$ABM$500,AB$2,0),Техника!$F$4:$ABM$4,"Часы",INDEX(Техника!$G$1:$ABN$500,AB$2,0),$A$18,INDEX(Техника!$H$1:$ABO$500,AB$2,0),"Д") -> 0
A21: П | B21: Погрузка, перевозка | C21: =SUMIFS(INDEX(Техника!$F$1:$ABM$500,C$2,0),Техника!$F$4:$ABM$4,"Часы",INDEX(Техника!$G$1:$ABN$500,C$2,0),$A$18,INDEX(Техника!$H$1:$ABO$500,C$2,0),"П") -> 0 | D21: =SUMIFS(INDEX(Техника!$F$1:$ABM$500,D$2,0),Техника!$F$4:$ABM$4,"Часы",INDEX(Техника!$G$1:$ABN$500,D$2,0),$A$18,INDEX(Техника!$H$1:$ABO$500,D$2,0),"П") -> 0 | E21: =SUMIFS(INDEX(Техника!$F$1:$ABM$500,E$2,0),Техника!$F$4:$ABM$4,"Часы",INDEX(Техника!$G$1:$ABN$500,E$2,0),$A$18,INDEX(Техника!$H$1:$ABO$500,E$2,0),"П") -> 0 | F21: =SUMIFS(INDEX(Техника!$F$1:$ABM$500,F$2,0),Техника!$F$4:$ABM$4,"Часы",INDEX(Техника!$G$1:$ABN$500,F$2,0),$A$18,INDEX(Техника!$H$1:$ABO$500,F$2,0),"П") -> 0 | G21: =SUMIFS(INDEX(Техника!$F$1:$ABM$500,G$2,0),Техника!$F$4:$ABM$4,"Часы",INDEX(Техника!$G$1:$ABN$500,G$2,0),$A$18,INDEX(Техника!$H$1:$ABO$500,G$2,0),"П") -> 0 | H21: =SUMIFS(INDEX(Техника!$F$1:$ABM$500,H$2,0),Техника!$F$4:$ABM$4,"Часы",INDEX(Техника!$G$1:$ABN$500,H$2,0),$A$18,INDEX(Техника!$H$1:$ABO$500,H$2,0),"П") -> 0 | I21: =SUMIFS(INDEX(Техника!$F$1:$ABM$500,I$2,0),Техника!$F$4:$ABM$4,"Часы",INDEX(Техника!$G$1:$ABN$500,I$2,0),$A$18,INDEX(Техника!$H$1:$ABO$500,I$2,0),"П") -> 0 | J21: =SUMIFS(INDEX(Техника!$F$1:$ABM$500,J$2,0),Техника!$F$4:$ABM$4,"Часы",INDEX(Техника!$G$1:$ABN$500,J$2,0),$A$18,INDEX(Техника!$H$1:$ABO$500,J$2,0),"П") -> 0 | ... AB21: =SUMIFS(INDEX(Техника!$F$1:$ABM$500,AB$2,0),Техника!$F$4:$ABM$4,"Часы",INDEX(Техника!$G$1:$ABN$500,AB$2,0),$A$18,INDEX(Техника!$H$1:$ABO$500,AB$2,0),"П") -> 0
A22: Л | B22: Перевозка людей | C22: =SUMIFS(INDEX(Техника!$F$1:$ABM$500,C$2,0),Техника!$F$4:$ABM$4,"Часы",INDEX(Техника!$G$1:$ABN$500,C$2,0),$A$18,INDEX(Техника!$H$1:$ABO$500,C$2,0),"Л") -> 0 | D22: =SUMIFS(INDEX(Техника!$F$1:$ABM$500,D$2,0),Техника!$F$4:$ABM$4,"Часы",INDEX(Техника!$G$1:$ABN$500,D$2,0),$A$18,INDEX(Техника!$H$1:$ABO$500,D$2,0),"Л") -> 0 | E22: =SUMIFS(INDEX(Техника!$F$1:$ABM$500,E$2,0),Техника!$F$4:$ABM$4,"Часы",INDEX(Техника!$G$1:$ABN$500,E$2,0),$A$18,INDEX(Техника!$H$1:$ABO$500,E$2,0),"Л") -> 0 | F22: =SUMIFS(INDEX(Техника!$F$1:$ABM$500,F$2,0),Техника!$F$4:$ABM$4,"Часы",INDEX(Техника!$G$1:$ABN$500,F$2,0),$A$18,INDEX(Техника!$H$1:$ABO$500,F$2,0),"Л") -> 0 | G22: =SUMIFS(INDEX(Техника!$F$1:$ABM$500,G$2,0),Техника!$F$4:$ABM$4,"Часы",INDEX(Техника!$G$1:$ABN$500,G$2,0),$A$18,INDEX(Техника!$H$1:$ABO$500,G$2,0),"Л") -> 0 | H22: =SUMIFS(INDEX(Техника!$F$1:$ABM$500,H$2,0),Техника!$F$4:$ABM$4,"Часы",INDEX(Техника!$G$1:$ABN$500,H$2,0),$A$18,INDEX(Техника!$H$1:$ABO$500,H$2,0),"Л") -> 0 | I22: =SUMIFS(INDEX(Техника!$F$1:$ABM$500,I$2,0),Техника!$F$4:$ABM$4,"Часы",INDEX(Техника!$G$1:$ABN$500,I$2,0),$A$18,INDEX(Техника!$H$1:$ABO$500,I$2,0),"Л") -> 0 | J22: =SUMIFS(INDEX(Техника!$F$1:$ABM$500,J$2,0),Техника!$F$4:$ABM$4,"Часы",INDEX(Техника!$G$1:$ABN$500,J$2,0),$A$18,INDEX(Техника!$H$1:$ABO$500,J$2,0),"Л") -> 0 | ... AB22: =SUMIFS(INDEX(Техника!$F$1:$ABM$500,AB$2,0),Техника!$F$4:$ABM$4,"Часы",INDEX(Техника!$G$1:$ABN$500,AB$2,0),$A$18,INDEX(Техника!$H$1:$ABO$500,AB$2,0),"Л") -> 0
